Workbook

Sheet 📊 Dashboard Ejecutivo
B1: 📊 DASHBOARD EJECUTIVO DE RENTABILIDAD INDUSTRIAL (CBC)
B2: Panel de Control para Toma de Decisiones | Actualizado: 18/06/2026
B5: 🔧 CONTROLES DE FILTRO
B6: Mes Selector: | C6: TODOS | D6: ⬇️ Usa las listas desplegables | E6: Turno Selector: | F6: TODOS
B8: 💰 INDICADORES CLAVE DE RENTABILIDAD
B9: 💵 INGRESOS TOTALES | C9: 💸 COSTO TOTAL OPERATIVO | D9: 💰 UTILIDAD PRODUCIDA | E9: 📈 MARGEN PRODUCCIÓN % | F9: 💎 UTILIDAD NETA | G9: 📊 MARGEN NETO %
B10: =SUMIFS('📅 Resumen Diario'!$J$5:$J$504,'📅 Resumen Diario'!$O$5:$O$504,IF($C$6="TODOS","*",$C$6),'📅 Resumen Diario'!$C$5:$C$504,IF($F$6="TODOS","*",$F$6)) -> 647038.09 | C10: =SUMIFS('📅 Resumen Diario'!$P$5:$P$504,'📅 Resumen Diario'!$O$5:$O$504,IF($C$6="TODOS","*",$C$6),'📅 Resumen Diario'!$C$5:$C$504,IF($F$6="TODOS","*",$F$6)) -> 435903.18 | D10: =SUMIFS('📅 Resumen Diario'!$L$5:$L$504,'📅 Resumen Diario'!$O$5:$O$504,IF($C$6="TODOS","*",$C$6),'📅 Resumen Diario'!$C$5:$C$504,IF($F$6="TODOS","*",$F$6)) -> 228707.86 | E10: =IF(B10=0,0,D10/B10) -> 0.35346893 | F10: =D10+D12+E12 -> 241127.86 | G10: =IF(B10=0,0,F10/B10) -> 0.37266409
B11: 📦 UNIDADES PRODUCIDAS | C11: 🏷️ ETIQUETAS PROCESADAS | D11: 🔄 REPOSICIÓN PALETIZANTE | E11: ⏰ INGRESOS H.EXTRAS
B12: =SUMIFS('📅 Resumen Diario'!$D$5:$D$504,'📅 Resumen Diario'!$O$5:$O$504,IF($C$6="TODOS","*",$C$6),'📅 Resumen Diario'!$C$5:$C$504,IF($F$6="TODOS","*",$F$6)) -> 53232.3 | C12: =SUMIFS('📅 Resumen Diario'!$G$5:$G$504,'📅 Resumen Diario'!$O$5:$O$504,IF($C$6="TODOS","*",$C$6),'📅 Resumen Diario'!$C$5:$C$504,IF($F$6="TODOS","*",$F$6)) -> 195255 | D12: =SUMIFS('📋 Detalle Diario'!$I$5:$I$489,'📋 Detalle Diario'!$H$5:$H$489,IF($C$6="TODOS","*",$C$6),'📋 Detalle Diario'!$C$5:$C$489,IF($F$6="TODOS","*",$F$6))*200 -> 0 | E12: =SUMIFS('📋 Detalle Diario'!$E$5:$E$489,'📋 Detalle Diario'!$H$5:$H$489,IF($C$6="TODOS","*",$C$6),'📋 Detalle Diario'!$C$5:$C$489,IF($F$6="TODOS","*",$F$6))*135 -> 12420
B14: 📢 DETECCIONES AUTOMÁTICAS DEL MIX (PARA EL PERÍODO SELECCIONADO)
B15: 🏆 Producto con Mayor Volumen | D15: 📉 Producto con Menor Volumen | F15: ⚠️ Producto con Menor Margen
B16: =IFERROR(INDEX(B20:B69, MATCH(MAX(C20:C69), C20:C69, 0)), "N/A") -> 2 Pack Pepsi + Roja 3 Litro | D16: =IFERROR(INDEX(B20:B69, MATCH(SMALL(C20:C69, COUNTIF(C20:C69, 0) + 1), C20:C69, 0)), "N/A") -> TRASIEGO MANTICA | F16: =IFERROR(INDEX(B20:B69, MATCH(MIN(F20:F69), F20:F69, 0)), "N/A") -> 18 Pack Pepsi + Roja 500 ML
B18: 📋 DETALLE DE DESEMPEÑO POR PRODUCTO Y MARGEN NETO
B19: Producto | C19: Unidades Producidas (Packs) | D19: Ingreso Total (C$) | E19: Costo Total Asignado (C$) | F19: Utilidad Neta Real (C$) | G19: Margen Neto %
B20: =IFERROR(INDEX('📦 Precios Proforma'!$B$5:$B$104, 1), "") -> 12 pack 12 oz pepsi +sabores | C20: =IF(B20="","",SUMIFS('📈 Datos Completos'!$E$7:$E$5000, '📈 Datos Completos'!$C$7:$C$5000, B20, '📈 Datos Completos'!$Q$7:$Q$5000, IF($C$6="TODOS","*",$C$6), '📈 Datos Completos'!$D$7:$D$5000, IF($F$6="TODOS","*",$F$6))) -> 252 | D20: =IF(B20="","",SUMIFS('📈 Datos Completos'!$K$7:$K$5000, '📈 Datos Completos'!$C$7:$C$5000, B20, '📈 Datos Completos'!$Q$7:$Q$5000, IF($C$6="TODOS","*",$C$6), '📈 Datos Completos'!$D$7:$D$5000, IF($F$6="TODOS","*",$F$6))) -> 1348.2 | E20: =IF(B20="","",SUMIFS('📈 Datos Completos'!$N$7:$N$5000, '📈 Datos Completos'!$C$7:$C$5000, B20, '📈 Datos Completos'!$Q$7:$Q$5000, IF($C$6="TODOS","*",$C$6), '📈 Datos Completos'!$D$7:$D$5000, IF($F$6="TODOS","*",$F$6))) -> 1348.8084 | F20: =IF(B20="","",SUMIFS('📈 Datos Completos'!$O$7:$O$5000, '📈 Datos Completos'!$C$7:$C$5000, B20, '📈 Datos Completos'!$Q$7:$Q$5000, IF($C$6="TODOS","*",$C$6), '📈 Datos Completos'!$D$7:$D$5000, IF($F$6="TODOS","*",$F$6))) -> -0.60839975 | G20: =IF(B20="","",IF(D20=0,0,F20/D20)) -> -0.00045126817
B21: =IFERROR(INDEX('📦 Precios Proforma'!$B$5:$B$104, 2), "") -> 12 Pack Adrenalina Rush 16 Onz | C21: =IF(B21="","",SUMIFS('📈 Datos Completos'!$E$7:$E$5000, '📈 Datos Completos'!$C$7:$C$5000, B21, '📈 Datos Completos'!$Q$7:$Q$5000, IF($C$6="TODOS","*",$C$6), '📈 Datos Completos'!$D$7:$D$5000, IF($F$6="TODOS","*",$F$6))) -> 0 | D21: =IF(B21="","",SUMIFS('📈 Datos Completos'!$K$7:$K$5000, '📈 Datos Completos'!$C$7:$C$5000, B21, '📈 Datos Completos'!$Q$7:$Q$5000, IF($C$6="TODOS","*",$C$6), '📈 Datos Completos'!$D$7:$D$5000, IF($F$6="TODOS","*",$F$6))) -> 0 | E21: =IF(B21="","",SUMIFS('📈 Datos Completos'!$N$7:$N$5000, '📈 Datos Completos'!$C$7:$C$5000, B21, '📈 Datos Completos'!$Q$7:$Q$5000, IF($C$6="TODOS","*",$C$6), '📈 Datos Completos'!$D$7:$D$5000, IF($F$6="TODOS","*",$F$6))) -> 0 | F21: =IF(B21="","",SUMIFS('📈 Datos Completos'!$O$7:$O$5000, '📈 Datos Completos'!$C$7:$C$5000, B21, '📈 Datos Completos'!$Q$7:$Q$5000, IF($C$6="TODOS","*",$C$6), '📈 Datos Completos'!$D$7:$D$5000, IF($F$6="TODOS","*",$F$6))) -> 0 | G21: =IF(B21="","",IF(D21=0,0,F21/D21)) -> 0
B22: =IFERROR(INDEX('📦 Precios Proforma'!$B$5:$B$104, 3), "") -> 12 PACK AMP 600 ML | C22: =IF(B22="","",SUMIFS('📈 Datos Completos'!$E$7:$E$5000, '📈 Datos Completos'!$C$7:$C$5000, B22, '📈 Datos Completos'!$Q$7:$Q$5000, IF($C$6="TODOS","*",$C$6), '📈 Datos Completos'!$D$7:$D$5000, IF($F$6="TODOS","*",$F$6))) -> 974 | D22: =IF(B22="","",SUMIFS('📈 Datos Completos'!$K$7:$K$5000, '📈 Datos Completos'!$C$7:$C$5000, B22, '📈 Datos Completos'!$Q$7:$Q$5000, IF($C$6="TODOS","*",$C$6), '📈 Datos Completos'!$D$7:$D$5000, IF($F$6="TODOS","*",$F$6))) -> 19113.1 | E22: =IF(B22="","",SUMIFS('📈 Datos Completos'!$N$7:$N$5000, '📈 Datos Completos'!$C$7:$C$5000, B22, '📈 Datos Completos'!$Q$7:$Q$5000, IF($C$6="TODOS","*",$C$6), '📈 Datos Completos'!$D$7:$D$5000, IF($F$6="TODOS","*",$F$6))) -> 12177.374 | F22: =IF(B22="","",SUMIFS('📈 Datos Completos'!$O$7:$O$5000, '📈 Datos Completos'!$C$7:$C$5000, B22, '📈 Datos Completos'!$Q$7:$Q$5000, IF($C$6="TODOS","*",$C$6), '📈 Datos Completos'!$D$7:$D$5000, IF($F$6="TODOS","*",$F$6))) -> 6935.7255 | G22: =IF(B22="","",IF(D22=0,0,F22/D22)) -> 0.36287811
B23: =IFERROR(INDEX('📦 Precios Proforma'!$B$5:$B$104, 4), "") -> 12 Pack California Surtido 400 ML | C23: =IF(B23="","",SUMIFS('📈 Datos Completos'!$E$7:$E$5000, '📈 Datos Completos'!$C$7:$C$5000, B23, '📈 Datos Completos'!$Q$7:$Q$5000, IF($C$6="TODOS","*",$C$6), '📈 Datos Completos'!$D$7:$D$5000, IF($F$6="TODOS","*",$F$6))) -> 1192 | D23: =IF(B23="","",SUMIFS('📈 Datos Completos'!$K$7:$K$5000, '📈 Datos Completos'!$C$7:$C$5000, B23, '📈 Datos Completos'!$Q$7:$Q$5000, IF($C$6="TODOS","*",$C$6), '📈 Datos Completos'!$D$7:$D$5000, IF($F$6="TODOS","*",$F$6))) -> 7672.2 | E23: =IF(B23="","",SUMIFS('📈 Datos Completos'!$N$7:$N$5000, '📈 Datos Completos'!$C$7:$C$5000, B23, '📈 Datos Completos'!$Q$7:$Q$5000, IF($C$6="TODOS","*",$C$6), '📈 Datos Completos'!$D$7:$D$5000, IF($F$6="TODOS","*",$F$6))) -> 9839.4712 | F23: =IF(B23="","",SUMIFS('📈 Datos Completos'!$O$7:$O$5000, '📈 Datos Completos'!$C$7:$C$5000, B23, '📈 Datos Completos'!$Q$7:$Q$5000, IF($C$6="TODOS","*",$C$6), '📈 Datos Completos'!$D$7:$D$5000, IF($F$6="TODOS","*",$F$6))) -> -2167.2712 | G23: =IF(B23="","",IF(D23=0,0,F23/D23)) -> -0.28248367
B24: =IFERROR(INDEX('📦 Precios Proforma'!$B$5:$B$104, 5), "") -> 12 Pack CSD 500 ML PET | C24: =IF(B24="","",SUMIFS('📈 Datos Completos'!$E$7:$E$5000, '📈 Datos Completos'!$C$7:$C$5000, B24, '📈 Datos Completos'!$Q$7:$Q$5000, IF($C$6="TODOS","*",$C$6), '📈 Datos Completos'!$D$7:$D$5000, IF($F$6="TODOS","*",$F$6))) -> 0 | D24: =IF(B24="","",SUMIFS('📈 Datos Completos'!$K$7:$K$5000, '📈 Datos Completos'!$C$7:$C$5000, B24, '📈 Datos Completos'!$Q$7:$Q$5000, IF($C$6="TODOS","*",$C$6), '📈 Datos Completos'!$D$7:$D$5000, IF($F$6="TODOS","*",$F$6))) -> 0 | E24: =IF(B24="","",SUMIFS('📈 Datos Completos'!$N$7:$N$5000, '📈 Datos Completos'!$C$7:$C$5000, B24, '📈 Datos Completos'!$Q$7:$Q$5000, IF($C$6="TODOS","*",$C$6), '📈 Datos Completos'!$D$7:$D$5000, IF($F$6="TODOS","*",$F$6))) -> 0 | F24: =IF(B24="","",SUMIFS('📈 Datos Completos'!$O$7:$O$5000, '📈 Datos Completos'!$C$7:$C$5000, B24, '📈 Datos Completos'!$Q$7:$Q$5000, IF($C$6="TODOS","*",$C$6), '📈 Datos Completos'!$D$7:$D$5000, IF($F$6="TODOS","*",$F$6))) -> 0 | G24: =IF(B24="","",IF(D24=0,0,F24/D24)) -> 0
B25: =IFERROR(INDEX('📦 Precios Proforma'!$B$5:$B$104, 6), "") -> 12 Pack Ensa Soda 500ml Pet | C25: =IF(B25="","",SUMIFS('📈 Datos Completos'!$E$7:$E$5000, '📈 Datos Completos'!$C$7:$C$5000, B25, '📈 Datos Completos'!$Q$7:$Q$5000, IF($C$6="TODOS","*",$C$6), '📈 Datos Completos'!$D$7:$D$5000, IF($F$6="TODOS","*",$F$6))) -> 438 | D25: =IF(B25="","",SUMIFS('📈 Datos Completos'!$K$7:$K$5000, '📈 Datos Completos'!$C$7:$C$5000, B25, '📈 Datos Completos'!$Q$7:$Q$5000, IF($C$6="TODOS","*",$C$6), '📈 Datos Completos'!$D$7:$D$5000, IF($F$6="TODOS","*",$F$6))) -> 10328.04 | E25: =IF(B25="","",SUMIFS('📈 Datos Completos'!$N$7:$N$5000, '📈 Datos Completos'!$C$7:$C$5000, B25, '📈 Datos Completos'!$Q$7:$Q$5000, IF($C$6="TODOS","*",$C$6), '📈 Datos Completos'!$D$7:$D$5000, IF($F$6="TODOS","*",$F$6))) -> 6194.2709 | F25: =IF(B25="","",SUMIFS('📈 Datos Completos'!$O$7:$O$5000, '📈 Datos Completos'!$C$7:$C$5000, B25, '📈 Datos Completos'!$Q$7:$Q$5000, IF($C$6="TODOS","*",$C$6), '📈 Datos Completos'!$D$7:$D$5000, IF($F$6="TODOS","*",$F$6))) -> 4133.7691 | G25: =IF(B25="","",IF(D25=0,0,F25/D25)) -> 0.4002472
B26: =IFERROR(INDEX('📦 Precios Proforma'!$B$5:$B$104, 7), "") -> 12 Pack Jugazzo Lata Surtido | C26: =IF(B26="","",SUMIFS('📈 Datos Completos'!$E$7:$E$5000, '📈 Datos Completos'!$C$7:$C$5000, B26, '📈 Datos Completos'!$Q$7:$Q$5000, IF($C$6="TODOS","*",$C$6), '📈 Datos Completos'!$D$7:$D$5000, IF($F$6="TODOS","*",$F$6))) -> 820 | D26: =IF(B26="","",SUMIFS('📈 Datos Completos'!$K$7:$K$5000, '📈 Datos Completos'!$C$7:$C$5000, B26, '📈 Datos Completos'!$Q$7:$Q$5000, IF($C$6="TODOS","*",$C$6), '📈 Datos Completos'!$D$7:$D$5000, IF($F$6="TODOS","*",$F$6))) -> 4874.4 | E26: =IF(B26="","",SUMIFS('📈 Datos Completos'!$N$7:$N$5000, '📈 Datos Completos'!$C$7:$C$5000, B26, '📈 Datos Completos'!$Q$7:$Q$5000, IF($C$6="TODOS","*",$C$6), '📈 Datos Completos'!$D$7:$D$5000, IF($F$6="TODOS","*",$F$6))) -> 12971.833 | F26: =IF(B26="","",SUMIFS('📈 Datos Completos'!$O$7:$O$5000, '📈 Datos Completos'!$C$7:$C$5000, B26, '📈 Datos Completos'!$Q$7:$Q$5000, IF($C$6="TODOS","*",$C$6), '📈 Datos Completos'!$D$7:$D$5000, IF($F$6="TODOS","*",$F$6))) -> -6383.1478 | G26: =IF(B26="","",IF(D26=0,0,F26/D26)) -> -1.3095248
B27: =IFERROR(INDEX('📦 Precios Proforma'!$B$5:$B$104, 8), "") -> 12 Pack LIPTON TE 500 ML | C27: =IF(B27="","",SUMIFS('📈 Datos Completos'!$E$7:$E$5000, '📈 Datos Completos'!$C$7:$C$5000, B27, '📈 Datos Completos'!$Q$7:$Q$5000, IF($C$6="TODOS","*",$C$6), '📈 Datos Completos'!$D$7:$D$5000, IF($F$6="TODOS","*",$F$6))) -> 0 | D27: =IF(B27="","",SUMIFS('📈 Datos Completos'!$K$7:$K$5000, '📈 Datos Completos'!$C$7:$C$5000, B27, '📈 Datos Completos'!$Q$7:$Q$5000, IF($C$6="TODOS","*",$C$6), '📈 Datos Completos'!$D$7:$D$5000, IF($F$6="TODOS","*",$F$6))) -> 0 | E27: =IF(B27="","",SUMIFS('📈 Datos Completos'!$N$7:$N$5000, '📈 Datos Completos'!$C$7:$C$5000, B27, '📈 Datos Completos'!$Q$7:$Q$5000, IF($C$6="TODOS","*",$C$6), '📈 Datos Completos'!$D$7:$D$5000, IF($F$6="TODOS","*",$F$6))) -> 0 | F27: =IF(B27="","",SUMIFS('📈 Datos Completos'!$O$7:$O$5000, '📈 Datos Completos'!$C$7:$C$5000, B27, '📈 Datos Completos'!$Q$7:$Q$5000, IF($C$6="TODOS","*",$C$6), '📈 Datos Completos'!$D$7:$D$5000, IF($F$6="TODOS","*",$F$6))) -> 0 | G27: =IF(B27="","",IF(D27=0,0,F27/D27)) -> 0
B28: =IFERROR(INDEX('📦 Precios Proforma'!$B$5:$B$104, 9), "") -> 12 Pack pepsi + sabores 12 onza | C28: =IF(B28="","",SUMIFS('📈 Datos Completos'!$E$7:$E$5000, '📈 Datos Completos'!$C$7:$C$5000, B28, '📈 Datos Completos'!$Q$7:$Q$5000, IF($C$6="TODOS","*",$C$6), '📈 Datos Completos'!$D$7:$D$5000, IF($F$6="TODOS","*",$F$6))) -> 924 | D28: =IF(B28="","",SUMIFS('📈 Datos Completos'!$K$7:$K$5000, '📈 Datos Completos'!$C$7:$C$5000, B28, '📈 Datos Completos'!$Q$7:$Q$5000, IF($C$6="TODOS","*",$C$6), '📈 Datos Completos'!$D$7:$D$5000, IF($F$6="TODOS","*",$F$6))) -> 5594.96 | E28: =IF(B28="","",SUMIFS('📈 Datos Completos'!$N$7:$N$5000, '📈 Datos Completos'!$C$7:$C$5000, B28, '📈 Datos Completos'!$Q$7:$Q$5000, IF($C$6="TODOS","*",$C$6), '📈 Datos Completos'!$D$7:$D$5000, IF($F$6="TODOS","*",$F$6))) -> 12500.119 | F28: =IF(B28="","",SUMIFS('📈 Datos Completos'!$O$7:$O$5000, '📈 Datos Completos'!$C$7:$C$5000, B28, '📈 Datos Completos'!$Q$7:$Q$5000, IF($C$6="TODOS","*",$C$6), '📈 Datos Completos'!$D$7:$D$5000, IF($F$6="TODOS","*",$F$6))) -> -3525.1592 | G28: =IF(B28="","",IF(D28=0,0,F28/D28)) -> -0.63005976
B29: =IFERROR(INDEX('📦 Precios Proforma'!$B$5:$B$104, 10), "") -> 12 Pack pepsi 1.5 ltr | C29: =IF(B29="","",SUMIFS('📈 Datos Completos'!$E$7:$E$5000, '📈 Datos Completos'!$C$7:$C$5000, B29, '📈 Datos Completos'!$Q$7:$Q$5000, IF($C$6="TODOS","*",$C$6), '📈 Datos Completos'!$D$7:$D$5000, IF($F$6="TODOS","*",$F$6))) -> 0 | D29: =IF(B29="","",SUMIFS('📈 Datos Completos'!$K$7:$K$5000, '📈 Datos Completos'!$C$7:$C$5000, B29, '📈 Datos Completos'!$Q$7:$Q$5000, IF($C$6="TODOS","*",$C$6), '📈 Datos Completos'!$D$7:$D$5000, IF($F$6="TODOS","*",$F$6))) -> 0 | E29: =IF(B29="","",SUMIFS('📈 Datos Completos'!$N$7:$N$5000, '📈 Datos Completos'!$C$7:$C$5000, B29, '📈 Datos Completos'!$Q$7:$Q$5000, IF($C$6="TODOS","*",$C$6), '📈 Datos Completos'!$D$7:$D$5000, IF($F$6="TODOS","*",$F$6))) -> 0 | F29: =IF(B29="","",SUMIFS('📈 Datos Completos'!$O$7:$O$5000, '📈 Datos Completos'!$C$7:$C$5000, B29, '📈 Datos Completos'!$Q$7:$Q$5000, IF($C$6="TODOS","*",$C$6), '📈 Datos Completos'!$D$7:$D$5000, IF($F$6="TODOS","*",$F$6))) -> 0 | G29: =IF(B29="","",IF(D29=0,0,F29/D29)) -> 0
B30: =IFERROR(INDEX('📦 Precios Proforma'!$B$5:$B$104, 11), "") -> 12 Pack Pepsi 500 ML | C30: =IF(B30="","",SUMIFS('📈 Datos Completos'!$E$7:$E$5000, '📈 Datos Completos'!$C$7:$C$5000, B30, '📈 Datos Completos'!$Q$7:$Q$5000, IF($C$6="TODOS","*",$C$6), '📈 Datos Completos'!$D$7:$D$5000, IF($F$6="TODOS","*",$F$6))) -> 48 | D30: =IF(B30="","",SUMIFS('📈 Datos Completos'!$K$7:$K$5000, '📈 Datos Completos'!$C$7:$C$5000, B30, '📈 Datos Completos'!$Q$7:$Q$5000, IF($C$6="TODOS","*",$C$6), '📈 Datos Completos'!$D$7:$D$5000, IF($F$6="TODOS","*",$F$6))) -> 847.2 | E30: =IF(B30="","",SUMIFS('📈 Datos Completos'!$N$7:$N$5000, '📈 Datos Completos'!$C$7:$C$5000, B30, '📈 Datos Completos'!$Q$7:$Q$5000, IF($C$6="TODOS","*",$C$6), '📈 Datos Completos'!$D$7:$D$5000, IF($F$6="TODOS","*",$F$6))) -> 1143.4699 | F30: =IF(B30="","",SUMIFS('📈 Datos Completos'!$O$7:$O$5000, '📈 Datos Completos'!$C$7:$C$5000, B30, '📈 Datos Completos'!$Q$7:$Q$5000, IF($C$6="TODOS","*",$C$6), '📈 Datos Completos'!$D$7:$D$5000, IF($F$6="TODOS","*",$F$6))) -> -296.26994 | G30: =IF(B30="","",IF(D30=0,0,F30/D30)) -> -0.34970484
B31: =IFERROR(INDEX('📦 Precios Proforma'!$B$5:$B$104, 12), "") -> 12 Pack Soda Ensa 500 ML | C31: =IF(B31="","",SUMIFS('📈 Datos Completos'!$E$7:$E$5000, '📈 Datos Completos'!$C$7:$C$5000, B31, '📈 Datos Completos'!$Q$7:$Q$5000, IF($C$6="TODOS","*",$C$6), '📈 Datos Completos'!$D$7:$D$5000, IF($F$6="TODOS","*",$F$6))) -> 640 | D31: =IF(B31="","",SUMIFS('📈 Datos Completos'!$K$7:$K$5000, '📈 Datos Completos'!$C$7:$C$5000, B31, '📈 Datos Completos'!$Q$7:$Q$5000, IF($C$6="TODOS","*",$C$6), '📈 Datos Completos'!$D$7:$D$5000, IF($F$6="TODOS","*",$F$6))) -> 11892.8 | E31: =IF(B31="","",SUMIFS('📈 Datos Completos'!$N$7:$N$5000, '📈 Datos Completos'!$C$7:$C$5000, B31, '📈 Datos Completos'!$Q$7:$Q$5000, IF($C$6="TODOS","*",$C$6), '📈 Datos Completos'!$D$7:$D$5000, IF($F$6="TODOS","*",$F$6))) -> 7271.34 | F31: =IF(B31="","",SUMIFS('📈 Datos Completos'!$O$7:$O$5000, '📈 Datos Completos'!$C$7:$C$5000, B31, '📈 Datos Completos'!$Q$7:$Q$5000, IF($C$6="TODOS","*",$C$6), '📈 Datos Completos'!$D$7:$D$5000, IF($F$6="TODOS","*",$F$6))) -> 4621.46 | G31: =IF(B31="","",IF(D31=0,0,F31/D31)) -> 0.3885931
B32: =IFERROR(INDEX('📦 Precios Proforma'!$B$5:$B$104, 13), "") -> 16 Pack Adrenaline 12 oz | C32: =IF(B32="","",SUMIFS('📈 Datos Completos'!$E$7:$E$5000, '📈 Datos Completos'!$C$7:$C$5000, B32, '📈 Datos Completos'!$Q$7:$Q$5000, IF($C$6="TODOS","*",$C$6), '📈 Datos Completos'!$D$7:$D$5000, IF($F$6="TODOS","*",$F$6))) -> 0 | D32: =IF(B32="","",SUMIFS('📈 Datos Completos'!$K$7:$K$5000, '📈 Datos Completos'!$C$7:$C$5000, B32, '📈 Datos Completos'!$Q$7:$Q$5000, IF($C$6="TODOS","*",$C$6), '📈 Datos Completos'!$D$7:$D$5000, IF($F$6="TODOS","*",$F$6))) -> 0 | E32: =IF(B32="","",SUMIFS('📈 Datos Completos'!$N$7:$N$5000, '📈 Datos Completos'!$C$7:$C$5000, B32, '📈 Datos Completos'!$Q$7:$Q$5000, IF($C$6="TODOS","*",$C$6), '📈 Datos Completos'!$D$7:$D$5000, IF($F$6="TODOS","*",$F$6))) -> 0 | F32: =IF(B32="","",SUMIFS('📈 Datos Completos'!$O$7:$O$5000, '📈 Datos Completos'!$C$7:$C$5000, B32, '📈 Datos Completos'!$Q$7:$Q$5000, IF($C$6="TODOS","*",$C$6), '📈 Datos Completos'!$D$7:$D$5000, IF($F$6="TODOS","*",$F$6))) -> 0 | G32: =IF(B32="","",IF(D32=0,0,F32/D32)) -> 0
B33: =IFERROR(INDEX('📦 Precios Proforma'!$B$5:$B$104, 14), "") -> 18 Pack 500 ml (pepsi,rojita) | C33: =IF(B33="","",SUMIFS('📈 Datos Completos'!$E$7:$E$5000, '📈 Datos Completos'!$C$7:$C$5000, B33, '📈 Datos Completos'!$Q$7:$Q$5000, IF($C$6="TODOS","*",$C$6), '📈 Datos Completos'!$D$7:$D$5000, IF($F$6="TODOS","*",$F$6))) -> 680 | D33: =IF(B33="","",SUMIFS('📈 Datos Completos'!$K$7:$K$5000, '📈 Datos Completos'!$C$7:$C$5000, B33, '📈 Datos Completos'!$Q$7:$Q$5000, IF($C$6="TODOS","*",$C$6), '📈 Datos Completos'!$D$7:$D$5000, IF($F$6="TODOS","*",$F$6))) -> 5472 | E33: =IF(B33="","",SUMIFS('📈 Datos Completos'!$N$7:$N$5000, '📈 Datos Completos'!$C$7:$C$5000, B33, '📈 Datos Completos'!$Q$7:$Q$5000, IF($C$6="TODOS","*",$C$6), '📈 Datos Completos'!$D$7:$D$5000, IF($F$6="TODOS","*",$F$6))) -> 8746.7261 | F33: =IF(B33="","",SUMIFS('📈 Datos Completos'!$O$7:$O$5000, '📈 Datos Completos'!$C$7:$C$5000, B33, '📈 Datos Completos'!$Q$7:$Q$5000, IF($C$6="TODOS","*",$C$6), '📈 Datos Completos'!$D$7:$D$5000, IF($F$6="TODOS","*",$F$6))) -> -3274.7261 | G33: =IF(B33="","",IF(D33=0,0,F33/D33)) -> -0.59845141
B34: =IFERROR(INDEX('📦 Precios Proforma'!$B$5:$B$104, 15), "") -> 18 PACK 500 ML PET SURTIDO | C34: =IF(B34="","",SUMIFS('📈 Datos Completos'!$E$7:$E$5000, '📈 Datos Completos'!$C$7:$C$5000, B34, '📈 Datos Completos'!$Q$7:$Q$5000, IF($C$6="TODOS","*",$C$6), '📈 Datos Completos'!$D$7:$D$5000, IF($F$6="TODOS","*",$F$6))) -> 0 | D34: =IF(B34="","",SUMIFS('📈 Datos Completos'!$K$7:$K$5000, '📈 Datos Completos'!$C$7:$C$5000, B34, '📈 Datos Completos'!$Q$7:$Q$5000, IF($C$6="TODOS","*",$C$6), '📈 Datos Completos'!$D$7:$D$5000, IF($F$6="TODOS","*",$F$6))) -> 0 | E34: =IF(B34="","",SUMIFS('📈 Datos Completos'!$N$7:$N$5000, '📈 Datos Completos'!$C$7:$C$5000, B34, '📈 Datos Completos'!$Q$7:$Q$5000, IF($C$6="TODOS","*",$C$6), '📈 Datos Completos'!$D$7:$D$5000, IF($F$6="TODOS","*",$F$6))) -> 0 | F34: =IF(B34="","",SUMIFS('📈 Datos Completos'!$O$7:$O$5000, '📈 Datos Completos'!$C$7:$C$5000, B34, '📈 Datos Completos'!$Q$7:$Q$5000, IF($C$6="TODOS","*",$C$6), '📈 Datos Completos'!$D$7:$D$5000, IF($F$6="TODOS","*",$F$6))) -> 0 | G34: =IF(B34="","",IF(D34=0,0,F34/D34)) -> 0
B35: =IFERROR(INDEX('📦 Precios Proforma'!$B$5:$B$104, 16), "") -> 18 Pack Be Light Surtido | C35: =IF(B35="","",SUMIFS('📈 Datos Completos'!$E$7:$E$5000, '📈 Datos Completos'!$C$7:$C$5000, B35, '📈 Datos Completos'!$Q$7:$Q$5000, IF($C$6="TODOS","*",$C$6), '📈 Datos Completos'!$D$7:$D$5000, IF($F$6="TODOS","*",$F$6))) -> 240 | D35: =IF(B35="","",SUMIFS('📈 Datos Completos'!$K$7:$K$5000, '📈 Datos Completos'!$C$7:$C$5000, B35, '📈 Datos Completos'!$Q$7:$Q$5000, IF($C$6="TODOS","*",$C$6), '📈 Datos Completos'!$D$7:$D$5000, IF($F$6="TODOS","*",$F$6))) -> 1728 | E35: =IF(B35="","",SUMIFS('📈 Datos Completos'!$N$7:$N$5000, '📈 Datos Completos'!$C$7:$C$5000, B35, '📈 Datos Completos'!$Q$7:$Q$5000, IF($C$6="TODOS","*",$C$6), '📈 Datos Completos'!$D$7:$D$5000, IF($F$6="TODOS","*",$F$6))) -> 2052.8185 | F35: =IF(B35="","",SUMIFS('📈 Datos Completos'!$O$7:$O$5000, '📈 Datos Completos'!$C$7:$C$5000, B35, '📈 Datos Completos'!$Q$7:$Q$5000, IF($C$6="TODOS","*",$C$6), '📈 Datos Completos'!$D$7:$D$5000, IF($F$6="TODOS","*",$F$6))) -> -324.81849 | G35: =IF(B35="","",IF(D35=0,0,F35/D35)) -> -0.18797366
B36: =IFERROR(INDEX('📦 Precios Proforma'!$B$5:$B$104, 17), "") -> 18 Pack Pepsi + Roja 500 ML | C36: =IF(B36="","",SUMIFS('📈 Datos Completos'!$E$7:$E$5000, '📈 Datos Completos'!$C$7:$C$5000, B36, '📈 Datos Completos'!$Q$7:$Q$5000, IF($C$6="TODOS","*",$C$6), '📈 Datos Completos'!$D$7:$D$5000, IF($F$6="TODOS","*",$F$6))) -> 1080 | D36: =IF(B36="","",SUMIFS('📈 Datos Completos'!$K$7:$K$5000, '📈 Datos Completos'!$C$7:$C$5000, B36, '📈 Datos Completos'!$Q$7:$Q$5000, IF($C$6="TODOS","*",$C$6), '📈 Datos Completos'!$D$7:$D$5000, IF($F$6="TODOS","*",$F$6))) -> 8496 | E36: =IF(B36="","",SUMIFS('📈 Datos Completos'!$N$7:$N$5000, '📈 Datos Completos'!$C$7:$C$5000, B36, '📈 Datos Completos'!$Q$7:$Q$5000, IF($C$6="TODOS","*",$C$6), '📈 Datos Completos'!$D$7:$D$5000, IF($F$6="TODOS","*",$F$6))) -> 19223.451 | F36: =IF(B36="","",SUMIFS('📈 Datos Completos'!$O$7:$O$5000, '📈 Datos Completos'!$C$7:$C$5000, B36, '📈 Datos Completos'!$Q$7:$Q$5000, IF($C$6="TODOS","*",$C$6), '📈 Datos Completos'!$D$7:$D$5000, IF($F$6="TODOS","*",$F$6))) -> -10727.451 | G36: =IF(B36="","",IF(D36=0,0,F36/D36)) -> -1.2626472
B37: =IFERROR(INDEX('📦 Precios Proforma'!$B$5:$B$104, 18), "") -> 2 Pack Pepsi + Ensa Toronja 3 Lts | C37: =IF(B37="","",SUMIFS('📈 Datos Completos'!$E$7:$E$5000, '📈 Datos Completos'!$C$7:$C$5000, B37, '📈 Datos Completos'!$Q$7:$Q$5000, IF($C$6="TODOS","*",$C$6), '📈 Datos Completos'!$D$7:$D$5000, IF($F$6="TODOS","*",$F$6))) -> 0 | D37: =IF(B37="","",SUMIFS('📈 Datos Completos'!$K$7:$K$5000, '📈 Datos Completos'!$C$7:$C$5000, B37, '📈 Datos Completos'!$Q$7:$Q$5000, IF($C$6="TODOS","*",$C$6), '📈 Datos Completos'!$D$7:$D$5000, IF($F$6="TODOS","*",$F$6))) -> 0 | E37: =IF(B37="","",SUMIFS('📈 Datos Completos'!$N$7:$N$5000, '📈 Datos Completos'!$C$7:$C$5000, B37, '📈 Datos Completos'!$Q$7:$Q$5000, IF($C$6="TODOS","*",$C$6), '📈 Datos Completos'!$D$7:$D$5000, IF($F$6="TODOS","*",$F$6))) -> 0 | F37: =IF(B37="","",SUMIFS('📈 Datos Completos'!$O$7:$O$5000, '📈 Datos Completos'!$C$7:$C$5000, B37, '📈 Datos Completos'!$Q$7:$Q$5000, IF($C$6="TODOS","*",$C$6), '📈 Datos Completos'!$D$7:$D$5000, IF($F$6="TODOS","*",$F$6))) -> 0 | G37: =IF(B37="","",IF(D37=0,0,F37/D37)) -> 0
B38: =IFERROR(INDEX('📦 Precios Proforma'!$B$5:$B$104, 19), "") -> 2 Pack Pepsi + Mirinda 3 Litro | C38: =IF(B38="","",SUMIFS('📈 Datos Completos'!$E$7:$E$5000, '📈 Datos Completos'!$C$7:$C$5000, B38, '📈 Datos Completos'!$Q$7:$Q$5000, IF($C$6="TODOS","*",$C$6), '📈 Datos Completos'!$D$7:$D$5000, IF($F$6="TODOS","*",$F$6))) -> 54 | D38: =IF(B38="","",SUMIFS('📈 Datos Completos'!$K$7:$K$5000, '📈 Datos Completos'!$C$7:$C$5000, B38, '📈 Datos Completos'!$Q$7:$Q$5000, IF($C$6="TODOS","*",$C$6), '📈 Datos Completos'!$D$7:$D$5000, IF($F$6="TODOS","*",$F$6))) -> 491.19 | E38: =IF(B38="","",SUMIFS('📈 Datos Completos'!$N$7:$N$5000, '📈 Datos Completos'!$C$7:$C$5000, B38, '📈 Datos Completos'!$Q$7:$Q$5000, IF($C$6="TODOS","*",$C$6), '📈 Datos Completos'!$D$7:$D$5000, IF($F$6="TODOS","*",$F$6))) -> 4028.5686 | F38: =IF(B38="","",SUMIFS('📈 Datos Completos'!$O$7:$O$5000, '📈 Datos Completos'!$C$7:$C$5000, B38, '📈 Datos Completos'!$Q$7:$Q$5000, IF($C$6="TODOS","*",$C$6), '📈 Datos Completos'!$D$7:$D$5000, IF($F$6="TODOS","*",$F$6))) -> -3253.8786 | G38: =IF(B38="","",IF(D38=0,0,F38/D38)) -> -6.6244806
B39: =IFERROR(INDEX('📦 Precios Proforma'!$B$5:$B$104, 20), "") -> 2 Pack Pepsi + Mirinda 3 lts | C39: =IF(B39="","",SUMIFS('📈 Datos Completos'!$E$7:$E$5000, '📈 Datos Completos'!$C$7:$C$5000, B39, '📈 Datos Completos'!$Q$7:$Q$5000, IF($C$6="TODOS","*",$C$6), '📈 Datos Completos'!$D$7:$D$5000, IF($F$6="TODOS","*",$F$6))) -> 0 | D39: =IF(B39="","",SUMIFS('📈 Datos Completos'!$K$7:$K$5000, '📈 Datos Completos'!$C$7:$C$5000, B39, '📈 Datos Completos'!$Q$7:$Q$5000, IF($C$6="TODOS","*",$C$6), '📈 Datos Completos'!$D$7:$D$5000, IF($F$6="TODOS","*",$F$6))) -> 0 | E39: =IF(B39="","",SUMIFS('📈 Datos Completos'!$N$7:$N$5000, '📈 Datos Completos'!$C$7:$C$5000, B39, '📈 Datos Completos'!$Q$7:$Q$5000, IF($C$6="TODOS","*",$C$6), '📈 Datos Completos'!$D$7:$D$5000, IF($F$6="TODOS","*",$F$6))) -> 0 | F39: =IF(B39="","",SUMIFS('📈 Datos Completos'!$O$7:$O$5000, '📈 Datos Completos'!$C$7:$C$5000, B39, '📈 Datos Completos'!$Q$7:$Q$5000, IF($C$6="TODOS","*",$C$6), '📈 Datos Completos'!$D$7:$D$5000, IF($F$6="TODOS","*",$F$6))) -> 0 | G39: =IF(B39="","",IF(D39=0,0,F39/D39)) -> 0
B40: =IFERROR(INDEX('📦 Precios Proforma'!$B$5:$B$104, 21), "") -> 2 Pack Pepsi + Roja 3 Litro | C40: =IF(B40="","",SUMIFS('📈 Datos Completos'!$E$7:$E$5000, '📈 Datos Completos'!$C$7:$C$5000, B40, '📈 Datos Completos'!$Q$7:$Q$5000, IF($C$6="TODOS","*",$C$6), '📈 Datos Completos'!$D$7:$D$5000, IF($F$6="TODOS","*",$F$6))) -> 14919 | D40: =IF(B40="","",SUMIFS('📈 Datos Completos'!$K$7:$K$5000, '📈 Datos Completos'!$C$7:$C$5000, B40, '📈 Datos Completos'!$Q$7:$Q$5000, IF($C$6="TODOS","*",$C$6), '📈 Datos Completos'!$D$7:$D$5000, IF($F$6="TODOS","*",$F$6))) -> 136938.92 | E40: =IF(B40="","",SUMIFS('📈 Datos Completos'!$N$7:$N$5000, '📈 Datos Completos'!$C$7:$C$5000, B40, '📈 Datos Completos'!$Q$7:$Q$5000, IF($C$6="TODOS","*",$C$6), '📈 Datos Completos'!$D$7:$D$5000, IF($F$6="TODOS","*",$F$6))) -> 77535.751 | F40: =IF(B40="","",SUMIFS('📈 Datos Completos'!$O$7:$O$5000, '📈 Datos Completos'!$C$7:$C$5000, B40, '📈 Datos Completos'!$Q$7:$Q$5000, IF($C$6="TODOS","*",$C$6), '📈 Datos Completos'!$D$7:$D$5000, IF($F$6="TODOS","*",$F$6))) -> 59653.316 | G40: =IF(B40="","",IF(D40=0,0,F40/D40)) -> 0.43561988
B41: =IFERROR(INDEX('📦 Precios Proforma'!$B$5:$B$104, 22), "") -> 2 Pack Pepsi + Rojita 3 Lts | C41: =IF(B41="","",SUMIFS('📈 Datos Completos'!$E$7:$E$5000, '📈 Datos Completos'!$C$7:$C$5000, B41, '📈 Datos Completos'!$Q$7:$Q$5000, IF($C$6="TODOS","*",$C$6), '📈 Datos Completos'!$D$7:$D$5000, IF($F$6="TODOS","*",$F$6))) -> 1788 | D41: =IF(B41="","",SUMIFS('📈 Datos Completos'!$K$7:$K$5000, '📈 Datos Completos'!$C$7:$C$5000, B41, '📈 Datos Completos'!$Q$7:$Q$5000, IF($C$6="TODOS","*",$C$6), '📈 Datos Completos'!$D$7:$D$5000, IF($F$6="TODOS","*",$F$6))) -> 15890.25 | E41: =IF(B41="","",SUMIFS('📈 Datos Completos'!$N$7:$N$5000, '📈 Datos Completos'!$C$7:$C$5000, B41, '📈 Datos Completos'!$Q$7:$Q$5000, IF($C$6="TODOS","*",$C$6), '📈 Datos Completos'!$D$7:$D$5000, IF($F$6="TODOS","*",$F$6))) -> 11080.352 | F41: =IF(B41="","",SUMIFS('📈 Datos Completos'!$O$7:$O$5000, '📈 Datos Completos'!$C$7:$C$5000, B41, '📈 Datos Completos'!$Q$7:$Q$5000, IF($C$6="TODOS","*",$C$6), '📈 Datos Completos'!$D$7:$D$5000, IF($F$6="TODOS","*",$F$6))) -> 4809.8976 | G41: =IF(B41="","",IF(D41=0,0,F41/D41)) -> 0.3026949
B42: =IFERROR(INDEX('📦 Precios Proforma'!$B$5:$B$104, 23), "") -> 2 Pack Pepsi + Toronja 3 Litro | C42: =IF(B42="","",SUMIFS('📈 Datos Completos'!$E$7:$E$5000, '📈 Datos Completos'!$C$7:$C$5000, B42, '📈 Datos Completos'!$Q$7:$Q$5000, IF($C$6="TODOS","*",$C$6), '📈 Datos Completos'!$D$7:$D$5000, IF($F$6="TODOS","*",$F$6))) -> 1620 | D42: =IF(B42="","",SUMIFS('📈 Datos Completos'!$K$7:$K$5000, '📈 Datos Completos'!$C$7:$C$5000, B42, '📈 Datos Completos'!$Q$7:$Q$5000, IF($C$6="TODOS","*",$C$6), '📈 Datos Completos'!$D$7:$D$5000, IF($F$6="TODOS","*",$F$6))) -> 13597.2 | E42: =IF(B42="","",SUMIFS('📈 Datos Completos'!$N$7:$N$5000, '📈 Datos Completos'!$C$7:$C$5000, B42, '📈 Datos Completos'!$Q$7:$Q$5000, IF($C$6="TODOS","*",$C$6), '📈 Datos Completos'!$D$7:$D$5000, IF($F$6="TODOS","*",$F$6))) -> 16529.829 | F42: =IF(B42="","",SUMIFS('📈 Datos Completos'!$O$7:$O$5000, '📈 Datos Completos'!$C$7:$C$5000, B42, '📈 Datos Completos'!$Q$7:$Q$5000, IF($C$6="TODOS","*",$C$6), '📈 Datos Completos'!$D$7:$D$5000, IF($F$6="TODOS","*",$F$6))) -> -2932.6286 | G42: =IF(B42="","",IF(D42=0,0,F42/D42)) -> -0.21567886
B43: =IFERROR(INDEX('📦 Precios Proforma'!$B$5:$B$104, 24), "") -> 24 Pack Gatorade Surtido | C43: =IF(B43="","",SUMIFS('📈 Datos Completos'!$E$7:$E$5000, '📈 Datos Completos'!$C$7:$C$5000, B43, '📈 Datos Completos'!$Q$7:$Q$5000, IF($C$6="TODOS","*",$C$6), '📈 Datos Completos'!$D$7:$D$5000, IF($F$6="TODOS","*",$F$6))) -> 2570 | D43: =IF(B43="","",SUMIFS('📈 Datos Completos'!$K$7:$K$5000, '📈 Datos Completos'!$C$7:$C$5000, B43, '📈 Datos Completos'!$Q$7:$Q$5000, IF($C$6="TODOS","*",$C$6), '📈 Datos Completos'!$D$7:$D$5000, IF($F$6="TODOS","*",$F$6))) -> 20424 | E43: =IF(B43="","",SUMIFS('📈 Datos Completos'!$N$7:$N$5000, '📈 Datos Completos'!$C$7:$C$5000, B43, '📈 Datos Completos'!$Q$7:$Q$5000, IF($C$6="TODOS","*",$C$6), '📈 Datos Completos'!$D$7:$D$5000, IF($F$6="TODOS","*",$F$6))) -> 16133.017 | F43: =IF(B43="","",SUMIFS('📈 Datos Completos'!$O$7:$O$5000, '📈 Datos Completos'!$C$7:$C$5000, B43, '📈 Datos Completos'!$Q$7:$Q$5000, IF($C$6="TODOS","*",$C$6), '📈 Datos Completos'!$D$7:$D$5000, IF($F$6="TODOS","*",$F$6))) -> 4290.9832 | G43: =IF(B43="","",IF(D43=0,0,F43/D43)) -> 0.21009514
B44: =IFERROR(INDEX('📦 Precios Proforma'!$B$5:$B$104, 25), "") -> 24 PACK GATORADE SURTIDO 500ML | C44: =IF(B44="","",SUMIFS('📈 Datos Completos'!$E$7:$E$5000, '📈 Datos Completos'!$C$7:$C$5000, B44, '📈 Datos Completos'!$Q$7:$Q$5000, IF($C$6="TODOS","*",$C$6), '📈 Datos Completos'!$D$7:$D$5000, IF($F$6="TODOS","*",$F$6))) -> 0 | D44: =IF(B44="","",SUMIFS('📈 Datos Completos'!$K$7:$K$5000, '📈 Datos Completos'!$C$7:$C$5000, B44, '📈 Datos Completos'!$Q$7:$Q$5000, IF($C$6="TODOS","*",$C$6), '📈 Datos Completos'!$D$7:$D$5000, IF($F$6="TODOS","*",$F$6))) -> 0 | E44: =IF(B44="","",SUMIFS('📈 Datos Completos'!$N$7:$N$5000, '📈 Datos Completos'!$C$7:$C$5000, B44, '📈 Datos Completos'!$Q$7:$Q$5000, IF($C$6="TODOS","*",$C$6), '📈 Datos Completos'!$D$7:$D$5000, IF($F$6="TODOS","*",$F$6))) -> 0 | F44: =IF(B44="","",SUMIFS('📈 Datos Completos'!$O$7:$O$5000, '📈 Datos Completos'!$C$7:$C$5000, B44, '📈 Datos Completos'!$Q$7:$Q$5000, IF($C$6="TODOS","*",$C$6), '📈 Datos Completos'!$D$7:$D$5000, IF($F$6="TODOS","*",$F$6))) -> 0 | G44: =IF(B44="","",IF(D44=0,0,F44/D44)) -> 0
B45: =IFERROR(INDEX('📦 Precios Proforma'!$B$5:$B$104, 26), "") -> 24 Pack Gatorade Surtido 600 ML | C45: =IF(B45="","",SUMIFS('📈 Datos Completos'!$E$7:$E$5000, '📈 Datos Completos'!$C$7:$C$5000, B45, '📈 Datos Completos'!$Q$7:$Q$5000, IF($C$6="TODOS","*",$C$6), '📈 Datos Completos'!$D$7:$D$5000, IF($F$6="TODOS","*",$F$6))) -> 720 | D45: =IF(B45="","",SUMIFS('📈 Datos Completos'!$K$7:$K$5000, '📈 Datos Completos'!$C$7:$C$5000, B45, '📈 Datos Completos'!$Q$7:$Q$5000, IF($C$6="TODOS","*",$C$6), '📈 Datos Completos'!$D$7:$D$5000, IF($F$6="TODOS","*",$F$6))) -> 6336 | E45: =IF(B45="","",SUMIFS('📈 Datos Completos'!$N$7:$N$5000, '📈 Datos Completos'!$C$7:$C$5000, B45, '📈 Datos Completos'!$Q$7:$Q$5000, IF($C$6="TODOS","*",$C$6), '📈 Datos Completos'!$D$7:$D$5000, IF($F$6="TODOS","*",$F$6))) -> 6384.9742 | F45: =IF(B45="","",SUMIFS('📈 Datos Completos'!$O$7:$O$5000, '📈 Datos Completos'!$C$7:$C$5000, B45, '📈 Datos Completos'!$Q$7:$Q$5000, IF($C$6="TODOS","*",$C$6), '📈 Datos Completos'!$D$7:$D$5000, IF($F$6="TODOS","*",$F$6))) -> -48.974161 | G45: =IF(B45="","",IF(D45=0,0,F45/D45)) -> -0.0077295078
...

Sheet 📦 Rentabilidad por Producto
B1: 📦 RENTABILIDAD DETALLADA POR PRODUCTO (COSTEO POR ABSORCIÓN PROPORCIONAL)
B2: Análisis de costos desagregado: Ingresos, Costos Laborales, Materiales y Rentabilidad por SKU
B4: Producto | C4: Unidades Producidas (Packs) | D4: Total Etiquetas | E4: Ingreso Empaque (C$) | F4: Ingreso Etiquetas (C$) | G4: Ingreso Total (C$) | H4: Costo Laboral Asignado (C$) | I4: Costo Material Etiquetas (C$) | J4: Costo Total Asignado (C$) | K4: Ganancia Neta (C$) | L4: Margen Neto %
B5: =IFERROR(INDEX('📦 Precios Proforma'!$B$5:$B$104, 1), "") -> 12 pack 12 oz pepsi +sabores | C5: =IF(B5="","",SUMIF('📈 Datos Completos'!$C$7:$C$5000, B5, '📈 Datos Completos'!$E$7:$E$5000)) -> 252 | D5: =IF(B5="","",SUMIF('📈 Datos Completos'!$C$7:$C$5000, B5, '📈 Datos Completos'!$H$7:$H$5000)) -> 252 | E5: =IF(B5="","",SUMIF('📈 Datos Completos'!$C$7:$C$5000, B5, '📈 Datos Completos'!$I$7:$I$5000)) -> 1093.68 | F5: =IF(B5="","",SUMIF('📈 Datos Completos'!$C$7:$C$5000, B5, '📈 Datos Completos'!$J$7:$J$5000)) -> 254.52 | G5: =IF(B5="","",SUMIF('📈 Datos Completos'!$C$7:$C$5000, B5, '📈 Datos Completos'!$K$7:$K$5000)) -> 1348.2 | H5: =IF(B5="","",SUMIF('📈 Datos Completos'!$C$7:$C$5000, B5, '📈 Datos Completos'!$L$7:$L$5000)) -> 1326.1284 | I5: =IF(B5="","",SUMIF('📈 Datos Completos'!$C$7:$C$5000, B5, '📈 Datos Completos'!$M$7:$M$5000)) -> 22.68 | J5: =IF(B5="","",SUMIF('📈 Datos Completos'!$C$7:$C$5000, B5, '📈 Datos Completos'!$N$7:$N$5000)) -> 1348.8084 | K5: =IF(B5="","",SUMIF('📈 Datos Completos'!$C$7:$C$5000, B5, '📈 Datos Completos'!$O$7:$O$5000)) -> -0.60839975 | L5: =IF(B5="","",IF(G5=0, 0, K5/G5)) -> -0.00045126817
B6: =IFERROR(INDEX('📦 Precios Proforma'!$B$5:$B$104, 2), "") -> 12 Pack Adrenalina Rush 16 Onz | C6: =IF(B6="","",SUMIF('📈 Datos Completos'!$C$7:$C$5000, B6, '📈 Datos Completos'!$E$7:$E$5000)) -> 0 | D6: =IF(B6="","",SUMIF('📈 Datos Completos'!$C$7:$C$5000, B6, '📈 Datos Completos'!$H$7:$H$5000)) -> 0 | E6: =IF(B6="","",SUMIF('📈 Datos Completos'!$C$7:$C$5000, B6, '📈 Datos Completos'!$I$7:$I$5000)) -> 0 | F6: =IF(B6="","",SUMIF('📈 Datos Completos'!$C$7:$C$5000, B6, '📈 Datos Completos'!$J$7:$J$5000)) -> 0 | G6: =IF(B6="","",SUMIF('📈 Datos Completos'!$C$7:$C$5000, B6, '📈 Datos Completos'!$K$7:$K$5000)) -> 0 | H6: =IF(B6="","",SUMIF('📈 Datos Completos'!$C$7:$C$5000, B6, '📈 Datos Completos'!$L$7:$L$5000)) -> 0 | I6: =IF(B6="","",SUMIF('📈 Datos Completos'!$C$7:$C$5000, B6, '📈 Datos Completos'!$M$7:$M$5000)) -> 0 | J6: =IF(B6="","",SUMIF('📈 Datos Completos'!$C$7:$C$5000, B6, '📈 Datos Completos'!$N$7:$N$5000)) -> 0 | K6: =IF(B6="","",SUMIF('📈 Datos Completos'!$C$7:$C$5000, B6, '📈 Datos Completos'!$O$7:$O$5000)) -> 0 | L6: =IF(B6="","",IF(G6=0, 0, K6/G6)) -> 0
B7: =IFERROR(INDEX('📦 Precios Proforma'!$B$5:$B$104, 3), "") -> 12 PACK AMP 600 ML | C7: =IF(B7="","",SUMIF('📈 Datos Completos'!$C$7:$C$5000, B7, '📈 Datos Completos'!$E$7:$E$5000)) -> 974 | D7: =IF(B7="","",SUMIF('📈 Datos Completos'!$C$7:$C$5000, B7, '📈 Datos Completos'!$H$7:$H$5000)) -> 11648 | E7: =IF(B7="","",SUMIF('📈 Datos Completos'!$C$7:$C$5000, B7, '📈 Datos Completos'!$I$7:$I$5000)) -> 6018.54 | F7: =IF(B7="","",SUMIF('📈 Datos Completos'!$C$7:$C$5000, B7, '📈 Datos Completos'!$J$7:$J$5000)) -> 13094.56 | G7: =IF(B7="","",SUMIF('📈 Datos Completos'!$C$7:$C$5000, B7, '📈 Datos Completos'!$K$7:$K$5000)) -> 19113.1 | H7: =IF(B7="","",SUMIF('📈 Datos Completos'!$C$7:$C$5000, B7, '📈 Datos Completos'!$L$7:$L$5000)) -> 11129.054 | I7: =IF(B7="","",SUMIF('📈 Datos Completos'!$C$7:$C$5000, B7, '📈 Datos Completos'!$M$7:$M$5000)) -> 1048.32 | J7: =IF(B7="","",SUMIF('📈 Datos Completos'!$C$7:$C$5000, B7, '📈 Datos Completos'!$N$7:$N$5000)) -> 12177.374 | K7: =IF(B7="","",SUMIF('📈 Datos Completos'!$C$7:$C$5000, B7, '📈 Datos Completos'!$O$7:$O$5000)) -> 6935.7255 | L7: =IF(B7="","",IF(G7=0, 0, K7/G7)) -> 0.36287811
B8: =IFERROR(INDEX('📦 Precios Proforma'!$B$5:$B$104, 4), "") -> 12 Pack California Surtido 400 ML | C8: =IF(B8="","",SUMIF('📈 Datos Completos'!$C$7:$C$5000, B8, '📈 Datos Completos'!$E$7:$E$5000)) -> 1192 | D8: =IF(B8="","",SUMIF('📈 Datos Completos'!$C$7:$C$5000, B8, '📈 Datos Completos'!$H$7:$H$5000)) -> 1236 | E8: =IF(B8="","",SUMIF('📈 Datos Completos'!$C$7:$C$5000, B8, '📈 Datos Completos'!$I$7:$I$5000)) -> 6233.44 | F8: =IF(B8="","",SUMIF('📈 Datos Completos'!$C$7:$C$5000, B8, '📈 Datos Completos'!$J$7:$J$5000)) -> 1438.76 | G8: =IF(B8="","",SUMIF('📈 Datos Completos'!$C$7:$C$5000, B8, '📈 Datos Completos'!$K$7:$K$5000)) -> 7672.2 | H8: =IF(B8="","",SUMIF('📈 Datos Completos'!$C$7:$C$5000, B8, '📈 Datos Completos'!$L$7:$L$5000)) -> 9728.2312 | I8: =IF(B8="","",SUMIF('📈 Datos Completos'!$C$7:$C$5000, B8, '📈 Datos Completos'!$M$7:$M$5000)) -> 111.24 | J8: =IF(B8="","",SUMIF('📈 Datos Completos'!$C$7:$C$5000, B8, '📈 Datos Completos'!$N$7:$N$5000)) -> 9839.4712 | K8: =IF(B8="","",SUMIF('📈 Datos Completos'!$C$7:$C$5000, B8, '📈 Datos Completos'!$O$7:$O$5000)) -> -2167.2712 | L8: =IF(B8="","",IF(G8=0, 0, K8/G8)) -> -0.28248367
B9: =IFERROR(INDEX('📦 Precios Proforma'!$B$5:$B$104, 5), "") -> 12 Pack CSD 500 ML PET | C9: =IF(B9="","",SUMIF('📈 Datos Completos'!$C$7:$C$5000, B9, '📈 Datos Completos'!$E$7:$E$5000)) -> 0 | D9: =IF(B9="","",SUMIF('📈 Datos Completos'!$C$7:$C$5000, B9, '📈 Datos Completos'!$H$7:$H$5000)) -> 0 | E9: =IF(B9="","",SUMIF('📈 Datos Completos'!$C$7:$C$5000, B9, '📈 Datos Completos'!$I$7:$I$5000)) -> 0 | F9: =IF(B9="","",SUMIF('📈 Datos Completos'!$C$7:$C$5000, B9, '📈 Datos Completos'!$J$7:$J$5000)) -> 0 | G9: =IF(B9="","",SUMIF('📈 Datos Completos'!$C$7:$C$5000, B9, '📈 Datos Completos'!$K$7:$K$5000)) -> 0 | H9: =IF(B9="","",SUMIF('📈 Datos Completos'!$C$7:$C$5000, B9, '📈 Datos Completos'!$L$7:$L$5000)) -> 0 | I9: =IF(B9="","",SUMIF('📈 Datos Completos'!$C$7:$C$5000, B9, '📈 Datos Completos'!$M$7:$M$5000)) -> 0 | J9: =IF(B9="","",SUMIF('📈 Datos Completos'!$C$7:$C$5000, B9, '📈 Datos Completos'!$N$7:$N$5000)) -> 0 | K9: =IF(B9="","",SUMIF('📈 Datos Completos'!$C$7:$C$5000, B9, '📈 Datos Completos'!$O$7:$O$5000)) -> 0 | L9: =IF(B9="","",IF(G9=0, 0, K9/G9)) -> 0
B10: =IFERROR(INDEX('📦 Precios Proforma'!$B$5:$B$104, 6), "") -> 12 Pack Ensa Soda 500ml Pet | C10: =IF(B10="","",SUMIF('📈 Datos Completos'!$C$7:$C$5000, B10, '📈 Datos Completos'!$E$7:$E$5000)) -> 438 | D10: =IF(B10="","",SUMIF('📈 Datos Completos'!$C$7:$C$5000, B10, '📈 Datos Completos'!$H$7:$H$5000)) -> 5694 | E10: =IF(B10="","",SUMIF('📈 Datos Completos'!$C$7:$C$5000, B10, '📈 Datos Completos'!$I$7:$I$5000)) -> 2641.14 | F10: =IF(B10="","",SUMIF('📈 Datos Completos'!$C$7:$C$5000, B10, '📈 Datos Completos'!$J$7:$J$5000)) -> 7686.9 | G10: =IF(B10="","",SUMIF('📈 Datos Completos'!$C$7:$C$5000, B10, '📈 Datos Completos'!$K$7:$K$5000)) -> 10328.04 | H10: =IF(B10="","",SUMIF('📈 Datos Completos'!$C$7:$C$5000, B10, '📈 Datos Completos'!$L$7:$L$5000)) -> 5681.8109 | I10: =IF(B10="","",SUMIF('📈 Datos Completos'!$C$7:$C$5000, B10, '📈 Datos Completos'!$M$7:$M$5000)) -> 512.46 | J10: =IF(B10="","",SUMIF('📈 Datos Completos'!$C$7:$C$5000, B10, '📈 Datos Completos'!$N$7:$N$5000)) -> 6194.2709 | K10: =IF(B10="","",SUMIF('📈 Datos Completos'!$C$7:$C$5000, B10, '📈 Datos Completos'!$O$7:$O$5000)) -> 4133.7691 | L10: =IF(B10="","",IF(G10=0, 0, K10/G10)) -> 0.4002472
B11: =IFERROR(INDEX('📦 Precios Proforma'!$B$5:$B$104, 7), "") -> 12 Pack Jugazzo Lata Surtido | C11: =IF(B11="","",SUMIF('📈 Datos Completos'!$C$7:$C$5000, B11, '📈 Datos Completos'!$E$7:$E$5000)) -> 820 | D11: =IF(B11="","",SUMIF('📈 Datos Completos'!$C$7:$C$5000, B11, '📈 Datos Completos'!$H$7:$H$5000)) -> 700 | E11: =IF(B11="","",SUMIF('📈 Datos Completos'!$C$7:$C$5000, B11, '📈 Datos Completos'!$I$7:$I$5000)) -> 4051.8 | F11: =IF(B11="","",SUMIF('📈 Datos Completos'!$C$7:$C$5000, B11, '📈 Datos Completos'!$J$7:$J$5000)) -> 822.6 | G11: =IF(B11="","",SUMIF('📈 Datos Completos'!$C$7:$C$5000, B11, '📈 Datos Completos'!$K$7:$K$5000)) -> 4874.4 | H11: =IF(B11="","",SUMIF('📈 Datos Completos'!$C$7:$C$5000, B11, '📈 Datos Completos'!$L$7:$L$5000)) -> 12908.833 | I11: =IF(B11="","",SUMIF('📈 Datos Completos'!$C$7:$C$5000, B11, '📈 Datos Completos'!$M$7:$M$5000)) -> 63 | J11: =IF(B11="","",SUMIF('📈 Datos Completos'!$C$7:$C$5000, B11, '📈 Datos Completos'!$N$7:$N$5000)) -> 12971.833 | K11: =IF(B11="","",SUMIF('📈 Datos Completos'!$C$7:$C$5000, B11, '📈 Datos Completos'!$O$7:$O$5000)) -> -6383.1478 | L11: =IF(B11="","",IF(G11=0, 0, K11/G11)) -> -1.3095248
B12: =IFERROR(INDEX('📦 Precios Proforma'!$B$5:$B$104, 8), "") -> 12 Pack LIPTON TE 500 ML | C12: =IF(B12="","",SUMIF('📈 Datos Completos'!$C$7:$C$5000, B12, '📈 Datos Completos'!$E$7:$E$5000)) -> 0 | D12: =IF(B12="","",SUMIF('📈 Datos Completos'!$C$7:$C$5000, B12, '📈 Datos Completos'!$H$7:$H$5000)) -> 0 | E12: =IF(B12="","",SUMIF('📈 Datos Completos'!$C$7:$C$5000, B12, '📈 Datos Completos'!$I$7:$I$5000)) -> 0 | F12: =IF(B12="","",SUMIF('📈 Datos Completos'!$C$7:$C$5000, B12, '📈 Datos Completos'!$J$7:$J$5000)) -> 0 | G12: =IF(B12="","",SUMIF('📈 Datos Completos'!$C$7:$C$5000, B12, '📈 Datos Completos'!$K$7:$K$5000)) -> 0 | H12: =IF(B12="","",SUMIF('📈 Datos Completos'!$C$7:$C$5000, B12, '📈 Datos Completos'!$L$7:$L$5000)) -> 0 | I12: =IF(B12="","",SUMIF('📈 Datos Completos'!$C$7:$C$5000, B12, '📈 Datos Completos'!$M$7:$M$5000)) -> 0 | J12: =IF(B12="","",SUMIF('📈 Datos Completos'!$C$7:$C$5000, B12, '📈 Datos Completos'!$N$7:$N$5000)) -> 0 | K12: =IF(B12="","",SUMIF('📈 Datos Completos'!$C$7:$C$5000, B12, '📈 Datos Completos'!$O$7:$O$5000)) -> 0 | L12: =IF(B12="","",IF(G12=0, 0, K12/G12)) -> 0
B13: =IFERROR(INDEX('📦 Precios Proforma'!$B$5:$B$104, 9), "") -> 12 Pack pepsi + sabores 12 onza | C13: =IF(B13="","",SUMIF('📈 Datos Completos'!$C$7:$C$5000, B13, '📈 Datos Completos'!$E$7:$E$5000)) -> 924 | D13: =IF(B13="","",SUMIF('📈 Datos Completos'!$C$7:$C$5000, B13, '📈 Datos Completos'!$H$7:$H$5000)) -> 924 | E13: =IF(B13="","",SUMIF('📈 Datos Completos'!$C$7:$C$5000, B13, '📈 Datos Completos'!$I$7:$I$5000)) -> 4537.96 | F13: =IF(B13="","",SUMIF('📈 Datos Completos'!$C$7:$C$5000, B13, '📈 Datos Completos'!$J$7:$J$5000)) -> 1057 | G13: =IF(B13="","",SUMIF('📈 Datos Completos'!$C$7:$C$5000, B13, '📈 Datos Completos'!$K$7:$K$5000)) -> 5594.96 | H13: =IF(B13="","",SUMIF('📈 Datos Completos'!$C$7:$C$5000, B13, '📈 Datos Completos'!$L$7:$L$5000)) -> 12416.959 | I13: =IF(B13="","",SUMIF('📈 Datos Completos'!$C$7:$C$5000, B13, '📈 Datos Completos'!$M$7:$M$5000)) -> 83.16 | J13: =IF(B13="","",SUMIF('📈 Datos Completos'!$C$7:$C$5000, B13, '📈 Datos Completos'!$N$7:$N$5000)) -> 12500.119 | K13: =IF(B13="","",SUMIF('📈 Datos Completos'!$C$7:$C$5000, B13, '📈 Datos Completos'!$O$7:$O$5000)) -> -3525.1592 | L13: =IF(B13="","",IF(G13=0, 0, K13/G13)) -> -0.63005976
B14: =IFERROR(INDEX('📦 Precios Proforma'!$B$5:$B$104, 10), "") -> 12 Pack pepsi 1.5 ltr | C14: =IF(B14="","",SUMIF('📈 Datos Completos'!$C$7:$C$5000, B14, '📈 Datos Completos'!$E$7:$E$5000)) -> 0 | D14: =IF(B14="","",SUMIF('📈 Datos Completos'!$C$7:$C$5000, B14, '📈 Datos Completos'!$H$7:$H$5000)) -> 0 | E14: =IF(B14="","",SUMIF('📈 Datos Completos'!$C$7:$C$5000, B14, '📈 Datos Completos'!$I$7:$I$5000)) -> 0 | F14: =IF(B14="","",SUMIF('📈 Datos Completos'!$C$7:$C$5000, B14, '📈 Datos Completos'!$J$7:$J$5000)) -> 0 | G14: =IF(B14="","",SUMIF('📈 Datos Completos'!$C$7:$C$5000, B14, '📈 Datos Completos'!$K$7:$K$5000)) -> 0 | H14: =IF(B14="","",SUMIF('📈 Datos Completos'!$C$7:$C$5000, B14, '📈 Datos Completos'!$L$7:$L$5000)) -> 0 | I14: =IF(B14="","",SUMIF('📈 Datos Completos'!$C$7:$C$5000, B14, '📈 Datos Completos'!$M$7:$M$5000)) -> 0 | J14: =IF(B14="","",SUMIF('📈 Datos Completos'!$C$7:$C$5000, B14, '📈 Datos Completos'!$N$7:$N$5000)) -> 0 | K14: =IF(B14="","",SUMIF('📈 Datos Completos'!$C$7:$C$5000, B14, '📈 Datos Completos'!$O$7:$O$5000)) -> 0 | L14: =IF(B14="","",IF(G14=0, 0, K14/G14)) -> 0
B15: =IFERROR(INDEX('📦 Precios Proforma'!$B$5:$B$104, 11), "") -> 12 Pack Pepsi 500 ML | C15: =IF(B15="","",SUMIF('📈 Datos Completos'!$C$7:$C$5000, B15, '📈 Datos Completos'!$E$7:$E$5000)) -> 48 | D15: =IF(B15="","",SUMIF('📈 Datos Completos'!$C$7:$C$5000, B15, '📈 Datos Completos'!$H$7:$H$5000)) -> 624 | E15: =IF(B15="","",SUMIF('📈 Datos Completos'!$C$7:$C$5000, B15, '📈 Datos Completos'!$I$7:$I$5000)) -> 216.96 | F15: =IF(B15="","",SUMIF('📈 Datos Completos'!$C$7:$C$5000, B15, '📈 Datos Completos'!$J$7:$J$5000)) -> 630.24 | G15: =IF(B15="","",SUMIF('📈 Datos Completos'!$C$7:$C$5000, B15, '📈 Datos Completos'!$K$7:$K$5000)) -> 847.2 | H15: =IF(B15="","",SUMIF('📈 Datos Completos'!$C$7:$C$5000, B15, '📈 Datos Completos'!$L$7:$L$5000)) -> 1087.3099 | I15: =IF(B15="","",SUMIF('📈 Datos Completos'!$C$7:$C$5000, B15, '📈 Datos Completos'!$M$7:$M$5000)) -> 56.16 | J15: =IF(B15="","",SUMIF('📈 Datos Completos'!$C$7:$C$5000, B15, '📈 Datos Completos'!$N$7:$N$5000)) -> 1143.4699 | K15: =IF(B15="","",SUMIF('📈 Datos Completos'!$C$7:$C$5000, B15, '📈 Datos Completos'!$O$7:$O$5000)) -> -296.26994 | L15: =IF(B15="","",IF(G15=0, 0, K15/G15)) -> -0.34970484
B16: =IFERROR(INDEX('📦 Precios Proforma'!$B$5:$B$104, 12), "") -> 12 Pack Soda Ensa 500 ML | C16: =IF(B16="","",SUMIF('📈 Datos Completos'!$C$7:$C$5000, B16, '📈 Datos Completos'!$E$7:$E$5000)) -> 640 | D16: =IF(B16="","",SUMIF('📈 Datos Completos'!$C$7:$C$5000, B16, '📈 Datos Completos'!$H$7:$H$5000)) -> 6862 | E16: =IF(B16="","",SUMIF('📈 Datos Completos'!$C$7:$C$5000, B16, '📈 Datos Completos'!$I$7:$I$5000)) -> 3421.3 | F16: =IF(B16="","",SUMIF('📈 Datos Completos'!$C$7:$C$5000, B16, '📈 Datos Completos'!$J$7:$J$5000)) -> 8471.5 | G16: =IF(B16="","",SUMIF('📈 Datos Completos'!$C$7:$C$5000, B16, '📈 Datos Completos'!$K$7:$K$5000)) -> 11892.8 | H16: =IF(B16="","",SUMIF('📈 Datos Completos'!$C$7:$C$5000, B16, '📈 Datos Completos'!$L$7:$L$5000)) -> 6653.76 | I16: =IF(B16="","",SUMIF('📈 Datos Completos'!$C$7:$C$5000, B16, '📈 Datos Completos'!$M$7:$M$5000)) -> 617.58 | J16: =IF(B16="","",SUMIF('📈 Datos Completos'!$C$7:$C$5000, B16, '📈 Datos Completos'!$N$7:$N$5000)) -> 7271.34 | K16: =IF(B16="","",SUMIF('📈 Datos Completos'!$C$7:$C$5000, B16, '📈 Datos Completos'!$O$7:$O$5000)) -> 4621.46 | L16: =IF(B16="","",IF(G16=0, 0, K16/G16)) -> 0.3885931
B17: =IFERROR(INDEX('📦 Precios Proforma'!$B$5:$B$104, 13), "") -> 16 Pack Adrenaline 12 oz | C17: =IF(B17="","",SUMIF('📈 Datos Completos'!$C$7:$C$5000, B17, '📈 Datos Completos'!$E$7:$E$5000)) -> 0 | D17: =IF(B17="","",SUMIF('📈 Datos Completos'!$C$7:$C$5000, B17, '📈 Datos Completos'!$H$7:$H$5000)) -> 0 | E17: =IF(B17="","",SUMIF('📈 Datos Completos'!$C$7:$C$5000, B17, '📈 Datos Completos'!$I$7:$I$5000)) -> 0 | F17: =IF(B17="","",SUMIF('📈 Datos Completos'!$C$7:$C$5000, B17, '📈 Datos Completos'!$J$7:$J$5000)) -> 0 | G17: =IF(B17="","",SUMIF('📈 Datos Completos'!$C$7:$C$5000, B17, '📈 Datos Completos'!$K$7:$K$5000)) -> 0 | H17: =IF(B17="","",SUMIF('📈 Datos Completos'!$C$7:$C$5000, B17, '📈 Datos Completos'!$L$7:$L$5000)) -> 0 | I17: =IF(B17="","",SUMIF('📈 Datos Completos'!$C$7:$C$5000, B17, '📈 Datos Completos'!$M$7:$M$5000)) -> 0 | J17: =IF(B17="","",SUMIF('📈 Datos Completos'!$C$7:$C$5000, B17, '📈 Datos Completos'!$N$7:$N$5000)) -> 0 | K17: =IF(B17="","",SUMIF('📈 Datos Completos'!$C$7:$C$5000, B17, '📈 Datos Completos'!$O$7:$O$5000)) -> 0 | L17: =IF(B17="","",IF(G17=0, 0, K17/G17)) -> 0
B18: =IFERROR(INDEX('📦 Precios Proforma'!$B$5:$B$104, 14), "") -> 18 Pack 500 ml (pepsi,rojita) | C18: =IF(B18="","",SUMIF('📈 Datos Completos'!$C$7:$C$5000, B18, '📈 Datos Completos'!$E$7:$E$5000)) -> 680 | D18: =IF(B18="","",SUMIF('📈 Datos Completos'!$C$7:$C$5000, B18, '📈 Datos Completos'!$H$7:$H$5000)) -> 680 | E18: =IF(B18="","",SUMIF('📈 Datos Completos'!$C$7:$C$5000, B18, '📈 Datos Completos'!$I$7:$I$5000)) -> 4703.6 | F18: =IF(B18="","",SUMIF('📈 Datos Completos'!$C$7:$C$5000, B18, '📈 Datos Completos'!$J$7:$J$5000)) -> 768.4 | G18: =IF(B18="","",SUMIF('📈 Datos Completos'!$C$7:$C$5000, B18, '📈 Datos Completos'!$K$7:$K$5000)) -> 5472 | H18: =IF(B18="","",SUMIF('📈 Datos Completos'!$C$7:$C$5000, B18, '📈 Datos Completos'!$L$7:$L$5000)) -> 8685.5261 | I18: =IF(B18="","",SUMIF('📈 Datos Completos'!$C$7:$C$5000, B18, '📈 Datos Completos'!$M$7:$M$5000)) -> 61.2 | J18: =IF(B18="","",SUMIF('📈 Datos Completos'!$C$7:$C$5000, B18, '📈 Datos Completos'!$N$7:$N$5000)) -> 8746.7261 | K18: =IF(B18="","",SUMIF('📈 Datos Completos'!$C$7:$C$5000, B18, '📈 Datos Completos'!$O$7:$O$5000)) -> -3274.7261 | L18: =IF(B18="","",IF(G18=0, 0, K18/G18)) -> -0.59845141
B19: =IFERROR(INDEX('📦 Precios Proforma'!$B$5:$B$104, 15), "") -> 18 PACK 500 ML PET SURTIDO | C19: =IF(B19="","",SUMIF('📈 Datos Completos'!$C$7:$C$5000, B19, '📈 Datos Completos'!$E$7:$E$5000)) -> 0 | D19: =IF(B19="","",SUMIF('📈 Datos Completos'!$C$7:$C$5000, B19, '📈 Datos Completos'!$H$7:$H$5000)) -> 0 | E19: =IF(B19="","",SUMIF('📈 Datos Completos'!$C$7:$C$5000, B19, '📈 Datos Completos'!$I$7:$I$5000)) -> 0 | F19: =IF(B19="","",SUMIF('📈 Datos Completos'!$C$7:$C$5000, B19, '📈 Datos Completos'!$J$7:$J$5000)) -> 0 | G19: =IF(B19="","",SUMIF('📈 Datos Completos'!$C$7:$C$5000, B19, '📈 Datos Completos'!$K$7:$K$5000)) -> 0 | H19: =IF(B19="","",SUMIF('📈 Datos Completos'!$C$7:$C$5000, B19, '📈 Datos Completos'!$L$7:$L$5000)) -> 0 | I19: =IF(B19="","",SUMIF('📈 Datos Completos'!$C$7:$C$5000, B19, '📈 Datos Completos'!$M$7:$M$5000)) -> 0 | J19: =IF(B19="","",SUMIF('📈 Datos Completos'!$C$7:$C$5000, B19, '📈 Datos Completos'!$N$7:$N$5000)) -> 0 | K19: =IF(B19="","",SUMIF('📈 Datos Completos'!$C$7:$C$5000, B19, '📈 Datos Completos'!$O$7:$O$5000)) -> 0 | L19: =IF(B19="","",IF(G19=0, 0, K19/G19)) -> 0
B20: =IFERROR(INDEX('📦 Precios Proforma'!$B$5:$B$104, 16), "") -> 18 Pack Be Light Surtido | C20: =IF(B20="","",SUMIF('📈 Datos Completos'!$C$7:$C$5000, B20, '📈 Datos Completos'!$E$7:$E$5000)) -> 240 | D20: =IF(B20="","",SUMIF('📈 Datos Completos'!$C$7:$C$5000, B20, '📈 Datos Completos'!$H$7:$H$5000)) -> 240 | E20: =IF(B20="","",SUMIF('📈 Datos Completos'!$C$7:$C$5000, B20, '📈 Datos Completos'!$I$7:$I$5000)) -> 1485.6 | F20: =IF(B20="","",SUMIF('📈 Datos Completos'!$C$7:$C$5000, B20, '📈 Datos Completos'!$J$7:$J$5000)) -> 242.4 | G20: =IF(B20="","",SUMIF('📈 Datos Completos'!$C$7:$C$5000, B20, '📈 Datos Completos'!$K$7:$K$5000)) -> 1728 | H20: =IF(B20="","",SUMIF('📈 Datos Completos'!$C$7:$C$5000, B20, '📈 Datos Completos'!$L$7:$L$5000)) -> 2031.2185 | I20: =IF(B20="","",SUMIF('📈 Datos Completos'!$C$7:$C$5000, B20, '📈 Datos Completos'!$M$7:$M$5000)) -> 21.6 | J20: =IF(B20="","",SUMIF('📈 Datos Completos'!$C$7:$C$5000, B20, '📈 Datos Completos'!$N$7:$N$5000)) -> 2052.8185 | K20: =IF(B20="","",SUMIF('📈 Datos Completos'!$C$7:$C$5000, B20, '📈 Datos Completos'!$O$7:$O$5000)) -> -324.81849 | L20: =IF(B20="","",IF(G20=0, 0, K20/G20)) -> -0.18797366
B21: =IFERROR(INDEX('📦 Precios Proforma'!$B$5:$B$104, 17), "") -> 18 Pack Pepsi + Roja 500 ML | C21: =IF(B21="","",SUMIF('📈 Datos Completos'!$C$7:$C$5000, B21, '📈 Datos Completos'!$E$7:$E$5000)) -> 1080 | D21: =IF(B21="","",SUMIF('📈 Datos Completos'!$C$7:$C$5000, B21, '📈 Datos Completos'!$H$7:$H$5000)) -> 1080 | E21: =IF(B21="","",SUMIF('📈 Datos Completos'!$C$7:$C$5000, B21, '📈 Datos Completos'!$I$7:$I$5000)) -> 7303.2 | F21: =IF(B21="","",SUMIF('📈 Datos Completos'!$C$7:$C$5000, B21, '📈 Datos Completos'!$J$7:$J$5000)) -> 1192.8 | G21: =IF(B21="","",SUMIF('📈 Datos Completos'!$C$7:$C$5000, B21, '📈 Datos Completos'!$K$7:$K$5000)) -> 8496 | H21: =IF(B21="","",SUMIF('📈 Datos Completos'!$C$7:$C$5000, B21, '📈 Datos Completos'!$L$7:$L$5000)) -> 19126.251 | I21: =IF(B21="","",SUMIF('📈 Datos Completos'!$C$7:$C$5000, B21, '📈 Datos Completos'!$M$7:$M$5000)) -> 97.2 | J21: =IF(B21="","",SUMIF('📈 Datos Completos'!$C$7:$C$5000, B21, '📈 Datos Completos'!$N$7:$N$5000)) -> 19223.451 | K21: =IF(B21="","",SUMIF('📈 Datos Completos'!$C$7:$C$5000, B21, '📈 Datos Completos'!$O$7:$O$5000)) -> -10727.451 | L21: =IF(B21="","",IF(G21=0, 0, K21/G21)) -> -1.2626472
B22: =IFERROR(INDEX('📦 Precios Proforma'!$B$5:$B$104, 18), "") -> 2 Pack Pepsi + Ensa Toronja 3 Lts | C22: =IF(B22="","",SUMIF('📈 Datos Completos'!$C$7:$C$5000, B22, '📈 Datos Completos'!$E$7:$E$5000)) -> 0 | D22: =IF(B22="","",SUMIF('📈 Datos Completos'!$C$7:$C$5000, B22, '📈 Datos Completos'!$H$7:$H$5000)) -> 0 | E22: =IF(B22="","",SUMIF('📈 Datos Completos'!$C$7:$C$5000, B22, '📈 Datos Completos'!$I$7:$I$5000)) -> 0 | F22: =IF(B22="","",SUMIF('📈 Datos Completos'!$C$7:$C$5000, B22, '📈 Datos Completos'!$J$7:$J$5000)) -> 0 | G22: =IF(B22="","",SUMIF('📈 Datos Completos'!$C$7:$C$5000, B22, '📈 Datos Completos'!$K$7:$K$5000)) -> 0 | H22: =IF(B22="","",SUMIF('📈 Datos Completos'!$C$7:$C$5000, B22, '📈 Datos Completos'!$L$7:$L$5000)) -> 0 | I22: =IF(B22="","",SUMIF('📈 Datos Completos'!$C$7:$C$5000, B22, '📈 Datos Completos'!$M$7:$M$5000)) -> 0 | J22: =IF(B22="","",SUMIF('📈 Datos Completos'!$C$7:$C$5000, B22, '📈 Datos Completos'!$N$7:$N$5000)) -> 0 | K22: =IF(B22="","",SUMIF('📈 Datos Completos'!$C$7:$C$5000, B22, '📈 Datos Completos'!$O$7:$O$5000)) -> 0 | L22: =IF(B22="","",IF(G22=0, 0, K22/G22)) -> 0
B23: =IFERROR(INDEX('📦 Precios Proforma'!$B$5:$B$104, 19), "") -> 2 Pack Pepsi + Mirinda 3 Litro | C23: =IF(B23="","",SUMIF('📈 Datos Completos'!$C$7:$C$5000, B23, '📈 Datos Completos'!$E$7:$E$5000)) -> 54 | D23: =IF(B23="","",SUMIF('📈 Datos Completos'!$C$7:$C$5000, B23, '📈 Datos Completos'!$H$7:$H$5000)) -> 162 | E23: =IF(B23="","",SUMIF('📈 Datos Completos'!$C$7:$C$5000, B23, '📈 Datos Completos'!$I$7:$I$5000)) -> 293.91 | F23: =IF(B23="","",SUMIF('📈 Datos Completos'!$C$7:$C$5000, B23, '📈 Datos Completos'!$J$7:$J$5000)) -> 197.28 | G23: =IF(B23="","",SUMIF('📈 Datos Completos'!$C$7:$C$5000, B23, '📈 Datos Completos'!$K$7:$K$5000)) -> 491.19 | H23: =IF(B23="","",SUMIF('📈 Datos Completos'!$C$7:$C$5000, B23, '📈 Datos Completos'!$L$7:$L$5000)) -> 4013.9886 | I23: =IF(B23="","",SUMIF('📈 Datos Completos'!$C$7:$C$5000, B23, '📈 Datos Completos'!$M$7:$M$5000)) -> 14.58 | J23: =IF(B23="","",SUMIF('📈 Datos Completos'!$C$7:$C$5000, B23, '📈 Datos Completos'!$N$7:$N$5000)) -> 4028.5686 | K23: =IF(B23="","",SUMIF('📈 Datos Completos'!$C$7:$C$5000, B23, '📈 Datos Completos'!$O$7:$O$5000)) -> -3253.8786 | L23: =IF(B23="","",IF(G23=0, 0, K23/G23)) -> -6.6244806
B24: =IFERROR(INDEX('📦 Precios Proforma'!$B$5:$B$104, 20), "") -> 2 Pack Pepsi + Mirinda 3 lts | C24: =IF(B24="","",SUMIF('📈 Datos Completos'!$C$7:$C$5000, B24, '📈 Datos Completos'!$E$7:$E$5000)) -> 0 | D24: =IF(B24="","",SUMIF('📈 Datos Completos'!$C$7:$C$5000, B24, '📈 Datos Completos'!$H$7:$H$5000)) -> 0 | E24: =IF(B24="","",SUMIF('📈 Datos Completos'!$C$7:$C$5000, B24, '📈 Datos Completos'!$I$7:$I$5000)) -> 0 | F24: =IF(B24="","",SUMIF('📈 Datos Completos'!$C$7:$C$5000, B24, '📈 Datos Completos'!$J$7:$J$5000)) -> 0 | G24: =IF(B24="","",SUMIF('📈 Datos Completos'!$C$7:$C$5000, B24, '📈 Datos Completos'!$K$7:$K$5000)) -> 0 | H24: =IF(B24="","",SUMIF('📈 Datos Completos'!$C$7:$C$5000, B24, '📈 Datos Completos'!$L$7:$L$5000)) -> 0 | I24: =IF(B24="","",SUMIF('📈 Datos Completos'!$C$7:$C$5000, B24, '📈 Datos Completos'!$M$7:$M$5000)) -> 0 | J24: =IF(B24="","",SUMIF('📈 Datos Completos'!$C$7:$C$5000, B24, '📈 Datos Completos'!$N$7:$N$5000)) -> 0 | K24: =IF(B24="","",SUMIF('📈 Datos Completos'!$C$7:$C$5000, B24, '📈 Datos Completos'!$O$7:$O$5000)) -> 0 | L24: =IF(B24="","",IF(G24=0, 0, K24/G24)) -> 0
B25: =IFERROR(INDEX('📦 Precios Proforma'!$B$5:$B$104, 21), "") -> 2 Pack Pepsi + Roja 3 Litro | C25: =IF(B25="","",SUMIF('📈 Datos Completos'!$C$7:$C$5000, B25, '📈 Datos Completos'!$E$7:$E$5000)) -> 14919 | D25: =IF(B25="","",SUMIF('📈 Datos Completos'!$C$7:$C$5000, B25, '📈 Datos Completos'!$H$7:$H$5000)) -> 44487 | E25: =IF(B25="","",SUMIF('📈 Datos Completos'!$C$7:$C$5000, B25, '📈 Datos Completos'!$I$7:$I$5000)) -> 82154.87 | F25: =IF(B25="","",SUMIF('📈 Datos Completos'!$C$7:$C$5000, B25, '📈 Datos Completos'!$J$7:$J$5000)) -> 54784.05 | G25: =IF(B25="","",SUMIF('📈 Datos Completos'!$C$7:$C$5000, B25, '📈 Datos Completos'!$K$7:$K$5000)) -> 136938.92 | H25: =IF(B25="","",SUMIF('📈 Datos Completos'!$C$7:$C$5000, B25, '📈 Datos Completos'!$L$7:$L$5000)) -> 73531.921 | I25: =IF(B25="","",SUMIF('📈 Datos Completos'!$C$7:$C$5000, B25, '📈 Datos Completos'!$M$7:$M$5000)) -> 4003.83 | J25: =IF(B25="","",SUMIF('📈 Datos Completos'!$C$7:$C$5000, B25, '📈 Datos Completos'!$N$7:$N$5000)) -> 77535.751 | K25: =IF(B25="","",SUMIF('📈 Datos Completos'!$C$7:$C$5000, B25, '📈 Datos Completos'!$O$7:$O$5000)) -> 59653.316 | L25: =IF(B25="","",IF(G25=0, 0, K25/G25)) -> 0.43561988
B26: =IFERROR(INDEX('📦 Precios Proforma'!$B$5:$B$104, 22), "") -> 2 Pack Pepsi + Rojita 3 Lts | C26: =IF(B26="","",SUMIF('📈 Datos Completos'!$C$7:$C$5000, B26, '📈 Datos Completos'!$E$7:$E$5000)) -> 1788 | D26: =IF(B26="","",SUMIF('📈 Datos Completos'!$C$7:$C$5000, B26, '📈 Datos Completos'!$H$7:$H$5000)) -> 5364 | E26: =IF(B26="","",SUMIF('📈 Datos Completos'!$C$7:$C$5000, B26, '📈 Datos Completos'!$I$7:$I$5000)) -> 9508.71 | F26: =IF(B26="","",SUMIF('📈 Datos Completos'!$C$7:$C$5000, B26, '📈 Datos Completos'!$J$7:$J$5000)) -> 6381.54 | G26: =IF(B26="","",SUMIF('📈 Datos Completos'!$C$7:$C$5000, B26, '📈 Datos Completos'!$K$7:$K$5000)) -> 15890.25 | H26: =IF(B26="","",SUMIF('📈 Datos Completos'!$C$7:$C$5000, B26, '📈 Datos Completos'!$L$7:$L$5000)) -> 10597.592 | I26: =IF(B26="","",SUMIF('📈 Datos Completos'!$C$7:$C$5000, B26, '📈 Datos Completos'!$M$7:$M$5000)) -> 482.76 | J26: =IF(B26="","",SUMIF('📈 Datos Completos'!$C$7:$C$5000, B26, '📈 Datos Completos'!$N$7:$N$5000)) -> 11080.352 | K26: =IF(B26="","",SUMIF('📈 Datos Completos'!$C$7:$C$5000, B26, '📈 Datos Completos'!$O$7:$O$5000)) -> 4809.8976 | L26: =IF(B26="","",IF(G26=0, 0, K26/G26)) -> 0.3026949
B27: =IFERROR(INDEX('📦 Precios Proforma'!$B$5:$B$104, 23), "") -> 2 Pack Pepsi + Toronja 3 Litro | C27: =IF(B27="","",SUMIF('📈 Datos Completos'!$C$7:$C$5000, B27, '📈 Datos Completos'!$E$7:$E$5000)) -> 1620 | D27: =IF(B27="","",SUMIF('📈 Datos Completos'!$C$7:$C$5000, B27, '📈 Datos Completos'!$H$7:$H$5000)) -> 4860 | E27: =IF(B27="","",SUMIF('📈 Datos Completos'!$C$7:$C$5000, B27, '📈 Datos Completos'!$I$7:$I$5000)) -> 8137.8 | F27: =IF(B27="","",SUMIF('📈 Datos Completos'!$C$7:$C$5000, B27, '📈 Datos Completos'!$J$7:$J$5000)) -> 5459.4 | G27: =IF(B27="","",SUMIF('📈 Datos Completos'!$C$7:$C$5000, B27, '📈 Datos Completos'!$K$7:$K$5000)) -> 13597.2 | H27: =IF(B27="","",SUMIF('📈 Datos Completos'!$C$7:$C$5000, B27, '📈 Datos Completos'!$L$7:$L$5000)) -> 16092.429 | I27: =IF(B27="","",SUMIF('📈 Datos Completos'!$C$7:$C$5000, B27, '📈 Datos Completos'!$M$7:$M$5000)) -> 437.4 | J27: =IF(B27="","",SUMIF('📈 Datos Completos'!$C$7:$C$5000, B27, '📈 Datos Completos'!$N$7:$N$5000)) -> 16529.829 | K27: =IF(B27="","",SUMIF('📈 Datos Completos'!$C$7:$C$5000, B27, '📈 Datos Completos'!$O$7:$O$5000)) -> -2932.6286 | L27: =IF(B27="","",IF(G27=0, 0, K27/G27)) -> -0.21567886
B28: =IFERROR(INDEX('📦 Precios Proforma'!$B$5:$B$104, 24), "") -> 24 Pack Gatorade Surtido | C28: =IF(B28="","",SUMIF('📈 Datos Completos'!$C$7:$C$5000, B28, '📈 Datos Completos'!$E$7:$E$5000)) -> 2570 | D28: =IF(B28="","",SUMIF('📈 Datos Completos'!$C$7:$C$5000, B28, '📈 Datos Completos'!$H$7:$H$5000)) -> 2570 | E28: =IF(B28="","",SUMIF('📈 Datos Completos'!$C$7:$C$5000, B28, '📈 Datos Completos'!$I$7:$I$5000)) -> 17556.3 | F28: =IF(B28="","",SUMIF('📈 Datos Completos'!$C$7:$C$5000, B28, '📈 Datos Completos'!$J$7:$J$5000)) -> 2867.7 | G28: =IF(B28="","",SUMIF('📈 Datos Completos'!$C$7:$C$5000, B28, '📈 Datos Completos'!$K$7:$K$5000)) -> 20424 | H28: =IF(B28="","",SUMIF('📈 Datos Completos'!$C$7:$C$5000, B28, '📈 Datos Completos'!$L$7:$L$5000)) -> 15901.717 | I28: =IF(B28="","",SUMIF('📈 Datos Completos'!$C$7:$C$5000, B28, '📈 Datos Completos'!$M$7:$M$5000)) -> 231.3 | J28: =IF(B28="","",SUMIF('📈 Datos Completos'!$C$7:$C$5000, B28, '📈 Datos Completos'!$N$7:$N$5000)) -> 16133.017 | K28: =IF(B28="","",SUMIF('📈 Datos Completos'!$C$7:$C$5000, B28, '📈 Datos Completos'!$O$7:$O$5000)) -> 4290.9832 | L28: =IF(B28="","",IF(G28=0, 0, K28/G28)) -> 0.21009514
B29: =IFERROR(INDEX('📦 Precios Proforma'!$B$5:$B$104, 25), "") -> 24 PACK GATORADE SURTIDO 500ML | C29: =IF(B29="","",SUMIF('📈 Datos Completos'!$C$7:$C$5000, B29, '📈 Datos Completos'!$E$7:$E$5000)) -> 0 | D29: =IF(B29="","",SUMIF('📈 Datos Completos'!$C$7:$C$5000, B29, '📈 Datos Completos'!$H$7:$H$5000)) -> 0 | E29: =IF(B29="","",SUMIF('📈 Datos Completos'!$C$7:$C$5000, B29, '📈 Datos Completos'!$I$7:$I$5000)) -> 0 | F29: =IF(B29="","",SUMIF('📈 Datos Completos'!$C$7:$C$5000, B29, '📈 Datos Completos'!$J$7:$J$5000)) -> 0 | G29: =IF(B29="","",SUMIF('📈 Datos Completos'!$C$7:$C$5000, B29, '📈 Datos Completos'!$K$7:$K$5000)) -> 0 | H29: =IF(B29="","",SUMIF('📈 Datos Completos'!$C$7:$C$5000, B29, '📈 Datos Completos'!$L$7:$L$5000)) -> 0 | I29: =IF(B29="","",SUMIF('📈 Datos Completos'!$C$7:$C$5000, B29, '📈 Datos Completos'!$M$7:$M$5000)) -> 0 | J29: =IF(B29="","",SUMIF('📈 Datos Completos'!$C$7:$C$5000, B29, '📈 Datos Completos'!$N$7:$N$5000)) -> 0 | K29: =IF(B29="","",SUMIF('📈 Datos Completos'!$C$7:$C$5000, B29, '📈 Datos Completos'!$O$7:$O$5000)) -> 0 | L29: =IF(B29="","",IF(G29=0, 0, K29/G29)) -> 0
