Workbook

Sheet Catalogos
A1: Nombre | B1: Cantidad | C1: ProrRateo en meses | D1: Costo unitario | E1: Costo mensual | H1: Nombre | I1: Cantidad
A2: Botas de seguridad | B2: 1 | C2: 12 | D2: 2500 | E2: =D2/C2 -> 208.33333 | H2: Transporte | I2: 800
A3: Casco | B3: 1 | C3: 6 | D3: 500 | E3: =D3/C3 -> 83.333333 | H3: Alimentación | I3: 1000
A4: Guantes | B4: 2 | C4: 4 | D4: 650 | E4: =D4/C4 -> 162.5 | H4: Telefono | I4: 250
A5: Camisas | B5: 3 | C5: 4 | D5: 450 | E5: =D5/C5 -> 112.5 | H5: Combustible | I5: 0
A6: Gafas | B6: 2 | C6: 4 | D6: 900 | E6: =D6/C6 -> 225 | H6: Depresiasión | I6: 0
A7: Cuchillas | B7: 1 | C7: 3 | D7: 200 | E7: =D7/C7 -> 66.666667 | H7: Ninguno | I7: 0
A8: Cinturon | B8: 1 | C8: 8 | D8: 750 | E8: =D8/C8 -> 93.75
A9: Chalecos de alta visibilidad | B9: 1 | C9: 4 | D9: 250 | E9: =D9/C9 -> 62.5
A10: Arneses de seguridad | B10: 1 | C10: 6 | D10: 600 | E10: =D10/C10 -> 100
A11: Protectores faciales | B11: 1 | C11: 6 | D11: 800 | E11: =D11/C11 -> 133.33333
A12: Protección respiratoria | B12: 1 | C12: 6 | D12: 1500 | E12: =D12/C12 -> 250
A13: Protectores térmicos | B13: 1 | C13: 12 | D13: 6000 | E13: =D13/C13 -> 500

Sheet Tarifario
A2: Tarifario de costos de facturación por horas laboradas
A3: COSTOS UNITARIOS | H3: Viaticos | L3: EPP
H4: Previsto | L4: Previsto
A5: Salario base | B5: 9000 | E5: Utilidad | F5: 20 | H5: Totales | J5: =SUM(J6:J12) -> 1800 | L5: Totales | N5: Precio | O5: Factor rep | P5: =SUM(P6:P12) -> 1472.1875
A6: Gastos Oerativos | H6: Transporte | J6: =VLOOKUP(H6,Catalogos!$H$2:$I$13,2,FALSE) -> 800 | L6: Guantes | N6: =VLOOKUP(L6,Catalogos!$A$2:$E$13,5,FALSE) -> 162.5 | O6: 0.05 | P6: =(N6*O6)+N6 -> 170.625
A7: Prestaciones | B7: Viáticos | C7: Epp | D7: Supervicion | E7: Cargos | F7: Seguros | H7: Alimentación | J7: =VLOOKUP(H7,Catalogos!$H$2:$I$13,2,FALSE) -> 1000 | L7: Camisas | N7: =VLOOKUP(L7,Catalogos!$A$2:$E$13,5,FALSE) -> 112.5 | O7: 0.05 | P7: =(N7*O7)+N7 -> 118.125
A8: =(B5*0.743) -> 6687 | B8: =J5 -> 1800 | C8: =P5 -> 1472.1875 | D8: 1000 | E8: 500 | F8: 300 | H8: Ninguno | J8: =VLOOKUP(H8,Catalogos!$H$2:$I$13,2,FALSE) -> 0 | L8: Botas de seguridad | N8: =VLOOKUP(L8,Catalogos!$A$2:$E$13,5,FALSE) -> 208.33333 | O8: 0.05 | P8: =(N8*O8)+N8 -> 218.75
A9: Costo mensual | B9: Utilidad | C9: Costos Totales | D9: Costo diario | E9: Costo hora | F9: Costo extra | H9: Ninguno | J9: =VLOOKUP(H9,Catalogos!$H$2:$I$13,2,FALSE) -> 0 | L9: Gafas | N9: =VLOOKUP(L9,Catalogos!$A$2:$E$13,5,FALSE) -> 225 | O9: 0.05 | P9: =(N9*O9)+N9 -> 236.25
A10: =A8+B8+C8+D8+E8+F8+B5 -> 20759.188 | B10: =(B5/(1-(F5/100)))-B5 -> 2250 | C10: =A10+B10 -> 23009.188 | D10: =C10/30 -> 766.97292 | E10: =D10/8 -> 95.871615 | F10: =((B5/30)/8)+E10 -> 133.37161 | H10: Ninguno | J10: =VLOOKUP(H10,Catalogos!$H$2:$I$13,2,FALSE) -> 0 | L10: Cinturon | N10: =VLOOKUP(L10,Catalogos!$A$2:$E$13,5,FALSE) -> 93.75 | O10: 0.05 | P10: =(N10*O10)+N10 -> 98.4375
H11: Ninguno | J11: =VLOOKUP(H11,Catalogos!$H$2:$I$13,2,FALSE) -> 0 | L11: Protectores térmicos | N11: =VLOOKUP(L11,Catalogos!$A$2:$E$13,5,FALSE) -> 500 | O11: 0.05 | P11: =(N11*O11)+N11 -> 525
H12: Ninguno | J12: =VLOOKUP(H12,Catalogos!$H$2:$I$13,2,FALSE) -> 0 | L12: Arneses de seguridad | N12: =VLOOKUP(L12,Catalogos!$A$2:$E$13,5,FALSE) -> 100 | O12: 0.05 | P12: =(N12*O12)+N12 -> 105

Sheet Equipo y maquinaria
A1: ID | B1: Nombre equipo | C1: TIPO | D1: Precio | E1: Cantidad | F1: Proyeccion de pago | G1: Proyeccion mensual | H1: =SUM(G2:G4) -> 22895
A2: 1 | B2: mesa de trabajo | C2: MAQUINARIAS | D2: 27800 | E2: 4 | F2: 12 | G2: =D2*E2/F2 -> 9266.6667
A3: 2 | B3: Selladoras* | C3: MAQUINARIAS | D3: 5175 | E3: 4 | F3: 6 | G3: =D3*E3/F3 -> 3450
A4: 3 | B4: Computadora con sistema | C4: MAQUINARIAS | D4: 61070 | E4: 2 | F4: 12 | G4: =D4*E4/F4 -> 10178.333

Sheet Matriz
F1: 3000 | G1: 222.78
A2: Descripción | B2: Termo nuevo | C2: Termo reutilizado | D2: Cinchos plasticos | E2: Horno | F2: Stickers cod barra | G2: Costo etiqueta | H2: Sticker promocional | I2: Tamaño | J2: Estibado | K2: Flejado | L2: Charolado/caja | M2: Tipo de tarima | N2: Adhesivo/tape | O2: Descripción breve
A3: 12 PACK CSD 500 ML PET | B3: TRUE | C3: FALSE | D3: FALSE | E3: TRUE | F3: 13 | G3: =(F3*G$1)/F$1 -> 0.96538 | I3: 2x1 | J3: TRUE | K3: TRUE | L3: FALSE | M3: Roja / Normal (según el cliente) | N3: FALSE | O3: Se etiqueta el producto unidad a unidad, se realiza surtido de producto en mesa se coloca manga de termo, posterior se pasa por horno, se coloca sticker, se estiba y fleja.
A4: Etiquetado por unidad Pepsi 500ml pet. | B4: FALSE | C4: FALSE | D4: FALSE | E4: FALSE | F4: 1 | G4: =(F4*G$1)/F$1 -> 0.07426 | I4: 2x1 | J4: FALSE | K4: FALSE | L4: FALSE | M4: Roja / Normal (según el cliente) | N4: FALSE | O4: Se etiqueta producto en mesa y posterior se utiliza en otros reprocesos.
A5: 12 Pack LIPTON TE 500 ML | B5: TRUE | C5: FALSE | D5: FALSE | E5: TRUE | F5: 13 | G5: =(F5*G$1)/F$1 -> 0.96538 | I5: 2x1 | J5: TRUE | K5: TRUE | L5: FALSE | M5: Roja / Normal (según el cliente) | N5: FALSE | O5: Se etiqueta el producto unidad a unidad, se realiza surtido de producto en mesa se coloca manga de termo, posterior se pasa por horno, se coloca sticker, se estiba y fleja.
A6: 24 Pack Gatorade Surtido 600 ML | B6: TRUE | C6: FALSE | D6: FALSE | E6: TRUE | F6: 1 | G6: =(F6*G$1)/F$1 -> 0.07426 | I6: 2x1 | J6: TRUE | K6: TRUE | L6: FALSE | M6: Roja / Normal (según el cliente) | N6: FALSE | O6: Se realiza surtido de producto en mesa, se coloca manga de termo, se pasa por horno, se etiqueta al paquete formado, posterior se estiba y fleja.
A7: GRANEL CD | B7: TRUE | C7: FALSE | D7: TRUE | E7: TRUE | F7: 0 | G7: =(F7*G$1)/F$1 -> 0 | J7: TRUE | K7: TRUE | L7: FALSE | M7: Normal | N7: FALSE | O7: Se arman packs con producto a granel surtido, se procede a colocar el producto en la manga de termoencogible y pasar por el horno de termo, se procede a estibar y embalar.
A8: Armado de Polines Walmart | B8: FALSE | C8: FALSE | D8: FALSE | E8: FALSE | F8: 0 | G8: =(F8*G$1)/F$1 -> 0 | J8: TRUE | K8: TRUE | L8: FALSE | M8: Roja | N8: FALSE | O8: Conformado completo de polines.
A9: 24 Pack Soda Ensa Lata | B9: FALSE | C9: TRUE | D9: FALSE | E9: FALSE | F9: 1 | G9: =(F9*G$1)/F$1 -> 0.07426 | I9: 2x1 | J9: TRUE | K9: TRUE | L9: FALSE | M9: Roja / Normal (según el cliente) | N9: FALSE | O9: Se coloca esticker al paquete, se reentarima y fleja
A10: Etiquetado Pepsi 12 Onz Pet | B10: FALSE | C10: FALSE | D10: FALSE | E10: FALSE | F10: 1 | G10: =(F10*G$1)/F$1 -> 0.07426 | I10: 2x1 | J10: FALSE | K10: FALSE | L10: FALSE | M10: Roja / Normal (según el cliente) | N10: FALSE | O10: Se etiqueta producto en mesa y posterior se utiliza en otros reprocesos.
A11: 2 Pack Pepsi + Rojita 3 Lts | B11: FALSE | C11: TRUE | D11: TRUE | E11: FALSE | F11: 3 | G11: =(F11*G$1)/F$1 -> 0.22278 | I11: 2x1 | J11: TRUE | K11: TRUE | L11: FALSE | M11: Roja / Normal (según el cliente) | N11: FALSE | O11: Se coloca producto en mesa, se etiqueta unidad por unidad, se coloca cincho plastico, se coloca estiker al paquete, posterior se estiba y fleja
A12: 4 Pack Pepsi + Rojita + Toronja 3 lts | B12: FALSE | C12: TRUE | D12: TRUE | E12: FALSE | F12: 5 | G12: =(F12*G$1)/F$1 -> 0.3713 | I12: 2x1 | J12: TRUE | K12: TRUE | L12: FALSE | M12: Roja / Normal (según el cliente) | N12: FALSE | O12: Se coloca producto en mesa, se etiqueta unidad por unidad, se coloca cincho plastico, se coloca estiker al paquete, posterior se estiba y fleja
A13: Impresion de Etiquetas | B13: FALSE | C13: FALSE | D13: FALSE | E13: FALSE | G13: =(F13*G$1)/F$1 -> 0 | I13: 2x1 | J13: FALSE | K13: FALSE | L13: FALSE | M13: Roja / Normal (según el cliente) | N13: FALSE | O13: Se realiza la impreson de stiker según necesidadde produccion
A14: 18 PACK 500 ML PET SURTIDO | B14: TRUE | C14: FALSE | D14: FALSE | E14: TRUE | F14: 19 | G14: =(F14*G$1)/F$1 -> 1.41094 | I14: 2x1 | J14: TRUE | K14: TRUE | L14: FALSE | M14: Roja / Normal (según el cliente) | N14: FALSE | O14: Se etiqueta el producto unidad a unidad, se realiza surtido de producto en mesa se coloca manga de termo, posterior se pasa por horno, se coloca sticker, se estiba y fleja.
A15: 6 Pack Lipton 250ml Tetra | B15: TRUE | C15: FALSE | D15: FALSE | E15: TRUE | F15: 1 | G15: =(F15*G$1)/F$1 -> 0.07426 | I15: 2x1 | J15: TRUE | K15: TRUE | L15: FALSE | M15: Roja / Normal (según el cliente) | N15: FALSE | O15: Se realiza surtido de producto en mesa, se coloca manga de termo, se pasa por horno, se etiqueta al paquete formado, posterior se estiba y fleja.
A16: 3 Pack Pepsi + Rojita + Ensa Toronja 3 Lts | B16: FALSE | C16: TRUE | D16: TRUE | E16: FALSE | F16: 4 | G16: =(F16*G$1)/F$1 -> 0.29704 | I16: 2x1 | J16: TRUE | K16: TRUE | L16: FALSE | M16: Roja / Normal (según el cliente) | N16: FALSE | O16: Se coloca producto en mesa, se etiqueta unidad por unidad, se coloca cincho plastico, se coloca estiker al paquete, posterior se estiba y fleja
A17: 18 Pack 500 ml (pepsi,rojita) | B17: TRUE | C17: FALSE | D17: FALSE | E17: TRUE | F17: 19 | G17: =(F17*G$1)/F$1 -> 1.41094 | I17: 2x1 | J17: TRUE | K17: TRUE | L17: FALSE | M17: Roja / Normal (según el cliente) | N17: FALSE | O17: Se etiqueta el producto unidad a unidad, se realiza surtido de producto en mesa se coloca manga de termo, posterior se pasa por horno, se coloca sticker, se estiba y fleja.
A18: 12 Pack California Surtido 400 ML | B18: TRUE | C18: FALSE | D18: FALSE | E18: TRUE | F18: 1 | G18: =(F18*G$1)/F$1 -> 0.07426 | I18: 2x1 | J18: TRUE | K18: TRUE | L18: FALSE | M18: Roja / Normal (según el cliente) | N18: FALSE | O18: Se realiza surtido de producto en mesa, se coloca manga de termo, se pasa por horno, se etiqueta paquete y posterior se estiba y fleja.
A19: 2 Pack Pepsi + Mirinda 3 lts | B19: FALSE | C19: TRUE | D19: TRUE | E19: FALSE | F19: 3 | G19: =(F19*G$1)/F$1 -> 0.22278 | I19: 2x1 | J19: TRUE | K19: TRUE | L19: FALSE | M19: Roja / Normal (según el cliente) | N19: FALSE | O19: Se coloca producto en mesa, se etiqueta unidad por unidad, se coloca cincho plastico, se coloca estiker al paquete, posterior se estiba y fleja
A20: 12 Pack Ensa Soda 500ml Pet | B20: TRUE | C20: FALSE | D20: FALSE | E20: TRUE | F20: 13 | G20: =(F20*G$1)/F$1 -> 0.96538 | I20: 2x1 | J20: TRUE | K20: TRUE | L20: FALSE | M20: Roja / Normal (según el cliente) | N20: FALSE | O20: Se etiqueta el producto unidad a unidad, se realiza surtido de producto en mesa se coloca manga de termo, posterior se pasa por horno, se coloca sticker, se estiba y fleja.
A21: Etiquetado Soda 500 ml | B21: FALSE | C21: FALSE | D21: FALSE | E21: FALSE | F21: 1 | G21: =(F21*G$1)/F$1 -> 0.07426 | I21: 2x1 | J21: FALSE | K21: FALSE | L21: FALSE | M21: Roja / Normal (según el cliente) | N21: FALSE | O21: Se etiqueta producto en mesa y posterior se utiliza en otros reprocesos.
A22: 8 Pack Pepsi Black 355Ml Lata | B22: TRUE | C22: FALSE | D22: FALSE | E22: TRUE | F22: 1 | G22: =(F22*G$1)/F$1 -> 0.07426 | I22: 2x1 | J22: TRUE | K22: TRUE | L22: FALSE | M22: Roja / Normal (según el cliente) | N22: FALSE | O22: Se realiza surtido de producto en mesa, se coloca manga de termo, se pasa por horno, se etiqueta paquete y posterior se estiba y fleja.
A23: 3 Pack Pepsi + Rojita + Ensa Toronja 3 Lts | B23: FALSE | C23: FALSE | D23: TRUE | E23: FALSE | F23: 8 | G23: =(F23*G$1)/F$1 -> 0.59408 | I23: 2x1 | J23: TRUE | K23: TRUE | L23: FALSE | M23: Roja / Normal (según el cliente) | N23: FALSE | O23: Se etiqueta unidad por unidad, se coloca cinchos, se estiba y se fleja
A24: 12 Pack Ensa Soda 500ml Pet | B24: FALSE | C24: TRUE | D24: FALSE | E24: FALSE | F24: 1 | G24: =(F24*G$1)/F$1 -> 0.07426 | I24: 2x1 | J24: TRUE | K24: TRUE | L24: FALSE | M24: Roja / Normal (según el cliente) | N24: FALSE | O24: Se coloca esticker al paquete, se reentarima y fleja
A25: Etiquetado Soda 500 ml | B25: FALSE | C25: FALSE | D25: FALSE | E25: FALSE | F25: 1 | G25: =(F25*G$1)/F$1 -> 0.07426 | I25: 2x1 | J25: FALSE | K25: FALSE | L25: FALSE | M25: Roja / Normal (según el cliente) | N25: FALSE | O25: Se etiqueta producto en mesa y posterior se utiliza en otros reprocesos.
... A29: 24 Pack Gatorade Surtido 600 ML | B29: FALSE | C29: FALSE | D29: FALSE | E29: FALSE | F29: 1 | G29: =(F29*G$1)/F$1 -> 0.07426 | I29: 2x1 | J29: TRUE | K29: TRUE | L29: FALSE | M29: Roja / Normal (según el cliente) | N29: FALSE | O29: Se coloca sticker a cada pack y posterior se estiba y embala.
A30: GRANEL CD | B30: FALSE | C30: FALSE | D30: FALSE | E30: FALSE | G30: =(F30*G$1)/F$1 -> 0 | J30: TRUE | K30: TRUE | L30: FALSE | M30: Roja / Normal (según el cliente) | N30: FALSE | O30: Se realiza reentarimado de producto y se fleja
A31: Armado de Polines Walmart | B31: FALSE | C31: FALSE | D31: FALSE | E31: FALSE | G31: =(F31*G$1)/F$1 -> 0 | J31: TRUE | K31: TRUE | L31: FALSE | M31: Roja / Normal (según el cliente) | N31: FALSE | O31: Se realiza reentarimado de producto y se fleja
A32: 24 Pack Soda Ensa Lata | B32: FALSE | C32: TRUE | D32: FALSE | E32: FALSE | F32: 1 | G32: =(F32*G$1)/F$1 -> 0.07426 | I32: 2x1 | J32: TRUE | K32: TRUE | L32: FALSE | M32: Roja / Normal (según el cliente) | N32: FALSE | O32: Se coloca esticker al paquete, se reentarima y fleja
A33: 2 Pack Pepsi + Rojita 3 Lts | B33: FALSE | C33: TRUE | D33: TRUE | E33: FALSE | F33: 9 | G33: =(F33*G$1)/F$1 -> 0.66834 | I33: 2x1 | J33: TRUE | K33: TRUE | L33: FALSE | M33: Roja / Normal (según el cliente) | N33: FALSE | O33: Se coloca producto en mesa, se etiqueta unidad por unidad, se coloca cincho plastico, se coloca estiker al paquete, posterior se estiba y fleja
A34: 2 Pack Pepsi + Ensa Toronja 3 Lts | B34: FALSE | C34: TRUE | D34: TRUE | E34: FALSE | F34: 9 | G34: =(F34*G$1)/F$1 -> 0.66834 | I34: 2x1 | J34: TRUE | K34: TRUE | L34: FALSE | M34: Roja / Normal (según el cliente) | N34: FALSE | O34: Se coloca producto en mesa, se etiqueta unidad por unidad, se coloca cincho plastico, se coloca estiker al paquete, posterior se estiba y fleja
A35: 3 Pack Pepsi + Rojita + Ensa Toronja 3 Lts | B35: FALSE | C35: TRUE | D35: TRUE | E35: FALSE | F35: 8 | G35: =(F35*G$1)/F$1 -> 0.59408 | I35: 2x1 | J35: TRUE | K35: TRUE | L35: FALSE | M35: Roja / Normal (según el cliente) | N35: FALSE | O35: Se coloca producto en mesa, se etiqueta unidad por unidad, se coloca cincho plastico, se coloca estiker al paquete, posterior se estiba y fleja
A36: 4 Pack Pepsi + Rojita + Toronja 3 lts | B36: FALSE | C36: TRUE | D36: TRUE | E36: FALSE | F36: 5 | G36: =(F36*G$1)/F$1 -> 0.3713 | I36: 2x1 | J36: TRUE | K36: TRUE | L36: FALSE | M36: Roja / Normal (según el cliente) | N36: FALSE | O36: Se coloca producto en mesa, se etiqueta unidad por unidad, se coloca cincho plastico, se coloca estiker al paquete, posterior se estiba y fleja
A37: 2 Pack Pepsi + Mirinda 3 lts | B37: FALSE | C37: TRUE | D37: TRUE | E37: FALSE | F37: 9 | G37: =(F37*G$1)/F$1 -> 0.66834 | I37: 2x1 | J37: TRUE | K37: TRUE | L37: FALSE | M37: Roja / Normal (según el cliente) | N37: FALSE | O37: Se coloca producto en mesa, se etiqueta unidad por unidad, se coloca cincho plastico, se coloca estiker al paquete, posterior se estiba y fleja
A38: 18 Pack 500 ml (pepsi,rojita) | B38: TRUE | C38: FALSE | D38: FALSE | E38: TRUE | F38: 19 | G38: =(F38*G$1)/F$1 -> 1.41094 | I38: 2x1 | J38: TRUE | K38: TRUE | L38: FALSE | M38: Roja / Normal (según el cliente) | N38: FALSE | O38: Se etiqueta el producto unidad a unidad, se realiza surtido de producto en mesa se coloca manga de termo, posterior se pasa por horno, se coloca sticker, se estiba y fleja.
A39: 12 Pack LIPTON TE 500 ML | B39: FALSE | C39: TRUE | D39: FALSE | E39: FALSE | F39: 1 | G39: =(F39*G$1)/F$1 -> 0.07426 | I39: 2x1 | J39: TRUE | K39: TRUE | L39: FALSE | M39: Roja / Normal (según el cliente) | N39: FALSE | O39: Se coloca esticker al paquete, se reentarima y fleja
A40: 12 Pack California Surtido 400 ML | B40: TRUE | C40: FALSE | D40: FALSE | E40: TRUE | F40: 1 | G40: =(F40*G$1)/F$1 -> 0.07426 | I40: 2x1 | J40: TRUE | K40: TRUE | L40: FALSE | M40: Roja / Normal (según el cliente) | N40: FALSE | O40: Se realiza surtido de producto en mesa, se coloca manga de termo, se pasa por horno, se etiqueta paquete y posterior se estiba y fleja.
A41: 3 Pack Pepsi + Ensa Toronja 3 Lts | B41: FALSE | C41: TRUE | D41: TRUE | E41: FALSE | F41: 8 | G41: =(F41*G$1)/F$1 -> 0.59408 | I41: 2x1 | J41: TRUE | K41: TRUE | L41: FALSE | M41: Roja / Normal (según el cliente) | N41: FALSE | O41: Se coloca producto en mesa, se etiqueta unidad por unidad, se coloca cincho plastico, se coloca estiker al paquete, posterior se estiba y fleja
A42: 24 Pack pepsi Black lata | B42: FALSE | C42: TRUE | D42: FALSE | E42: FALSE | F42: 1 | G42: =(F42*G$1)/F$1 -> 0.07426 | I42: 2x1 | J42: TRUE | K42: TRUE | L42: FALSE | M42: Roja / Normal (según el cliente) | N42: FALSE | O42: Se coloca esticker al paquete, se reentarima y fleja
A43: 16 Pack Adrenaline 12 oz | B43: TRUE | C43: FALSE | D43: FALSE | E43: TRUE | F43: 1 | G43: =(F43*G$1)/F$1 -> 0.07426 | I43: 2x1 | J43: TRUE | K43: TRUE | L43: FALSE | M43: Roja / Normal (según el cliente) | N43: FALSE | O43: Se realiza surtido de producto en mesa, se coloca manga de termo, se pasa por horno, se etiqueta paquete y posterior se estiba y fleja.
...

Sheet Costos produccion
A2: Tarifario de costos de facturación por producción
A4: Producto | B4: Produccion diaria | C4: Mano de obra unitaria | D4: Materiales | E4: Margen de merma | F4: Amortización por Unidad | G4: Tarifa total | H4: Tarifa unitaria
A5: 12 PACK CSD 500 ML PET | B5: 192 | C5: =(Tarifario!D$10/'Costos produccion'!B5) -> 3.9946506 | D5: =(VLOOKUP(A5,Tabla1[[Descripción]:[Costo etiqueta]],7,FALSE)*B5)+0.7*B5 -> 319.75296 | E5: =D5*0.05 -> 15.987648 | F5: ='Equipo y maquinaria'!H$1/(B5*6*24.5) -> 0.81118906 | G5: =(C5*B5)+D5+E5+F5 -> 1103.5247 | H5: =G5/B5 -> 5.7475246
A6: 12 Pack LIPTON TE 500 ML | B6: 192 | C6: =(Tarifario!D$10/'Costos produccion'!B6) -> 3.9946506 | D6: =(VLOOKUP(A6,Tabla1[[Descripción]:[Costo etiqueta]],7,FALSE)*B6)+0.7*B6 -> 319.75296 | E6: =D6*0.05 -> 15.987648 | F6: ='Equipo y maquinaria'!H$1/(B6*6*24.5) -> 0.81118906 | G6: =(C6*B6)+D6+E6+F6 -> 1103.5247 | H6: =G6/B6 -> 5.7475246
A7: 24 Pack Gatorade Surtido 600 ML | B7: 140 | C7: =(Tarifario!D$10/'Costos produccion'!B7) -> 5.478378 | D7: =(VLOOKUP(A7,Tabla1[[Descripción]:[Costo etiqueta]],7,FALSE)*B7)+0.7*B7 -> 108.3964 | E7: =D7*0.05 -> 5.41982 | F7: ='Equipo y maquinaria'!H$1/(B7*6*24.5) -> 1.1124879 | G7: =(C7*B7)+D7+E7+F7 -> 881.90162 | H7: =G7/B7 -> 6.2992973
A8: 24 Pack Soda Ensa Lata | B8: 140 | C8: =(Tarifario!D$10/'Costos produccion'!B8) -> 5.478378 | D8: =(VLOOKUP(A8,Tabla1[[Descripción]:[Costo etiqueta]],7,FALSE)*B8)+0.7*B8 -> 108.3964 | E8: =D8*0.05 -> 5.41982 | F8: ='Equipo y maquinaria'!H$1/(B8*6*24.5) -> 1.1124879 | G8: =(C8*B8)+D8+E8+F8 -> 881.90162 | H8: =G8/B8 -> 6.2992973
A9: 2 Pack Pepsi + Rojita 3 Lts | B9: 3894 | C9: =(Tarifario!D$10/'Costos produccion'!B9) -> 0.19696274 | D9: =(VLOOKUP(A9,Tabla1[[Descripción]:[Costo etiqueta]],7,FALSE)*B9)+0.7*B9 -> 3593.3053 | E9: =D9*0.05 -> 179.66527 | F9: ='Equipo y maquinaria'!H$1/(B9*6*24.5) -> 0.039996995 | G9: =(C9*B9)+D9+E9+F9 -> 4539.9835 | H9: =G9/B9 -> 1.165892
A10: 4 Pack Pepsi + Rojita + Toronja 3 lts | B10: 1833 | C10: =(Tarifario!D$10/'Costos produccion'!B10) -> 0.41842494 | D10: =(VLOOKUP(A10,Tabla1[[Descripción]:[Costo etiqueta]],7,FALSE)*B10)+0.7*B10 -> 1963.6929 | E10: =D10*0.05 -> 98.184645 | F10: ='Equipo y maquinaria'!H$1/(B10*6*24.5) -> 0.084969067 | G10: =(C10*B10)+D10+E10+F10 -> 2828.9354 | H10: =G10/B10 -> 1.5433363
A11: 18 PACK 500 ML PET SURTIDO | B11: 379 | C11: =(Tarifario!D$10/'Costos produccion'!B11) -> 2.0236752 | D11: =(VLOOKUP(A11,Tabla1[[Descripción]:[Costo etiqueta]],7,FALSE)*B11)+0.7*B11 -> 800.04626 | E11: =D11*0.05 -> 40.002313 | F11: ='Equipo y maquinaria'!H$1/(B11*6*24.5) -> 0.41094538 | G11: =(C11*B11)+D11+E11+F11 -> 1607.4324 | H11: =G11/B11 -> 4.2412465
A12: 6 Pack Lipton 250ml Tetra | B12: 364 | C12: =(Tarifario!D$10/'Costos produccion'!B12) -> 2.1070685 | D12: =(VLOOKUP(A12,Tabla1[[Descripción]:[Costo etiqueta]],7,FALSE)*B12)+0.7*B12 -> 281.83064 | E12: =D12*0.05 -> 14.091532 | F12: ='Equipo y maquinaria'!H$1/(B12*6*24.5) -> 0.42787994 | G12: =(C12*B12)+D12+E12+F12 -> 1063.323 | H12: =G12/B12 -> 2.9212169
A13: 3 Pack Pepsi + Rojita + Ensa Toronja 3 Lts | B13: 1635 | C13: =(Tarifario!D$10/'Costos produccion'!B13) -> 0.46909659 | D13: =(VLOOKUP(A13,Tabla1[[Descripción]:[Costo etiqueta]],7,FALSE)*B13)+0.7*B13 -> 1630.1604 | E13: =D13*0.05 -> 81.50802 | F13: ='Equipo y maquinaria'!H$1/(B13*6*24.5) -> 0.095258899 | G13: =(C13*B13)+D13+E13+F13 -> 2478.7366 | H13: =G13/B13 -> 1.5160468
A14: 18 Pack 500 ml (pepsi,rojita) | B14: 155 | C14: =(Tarifario!D$10/'Costos produccion'!B14) -> 4.9482124 | D14: =(VLOOKUP(A14,Tabla1[[Descripción]:[Costo etiqueta]],7,FALSE)*B14)+0.7*B14 -> 327.1957 | E14: =D14*0.05 -> 16.359785 | F14: ='Equipo y maquinaria'!H$1/(B14*6*24.5) -> 1.0048277 | G14: =(C14*B14)+D14+E14+F14 -> 1111.5332 | H14: =G14/B14 -> 7.1711821
A15: 12 Pack California Surtido 400 ML | B15: 296 | C15: =(Tarifario!D$10/'Costos produccion'!B15) -> 2.5911247 | D15: =(VLOOKUP(A15,Tabla1[[Descripción]:[Costo etiqueta]],7,FALSE)*B15)+0.7*B15 -> 229.18096 | E15: =D15*0.05 -> 11.459048 | F15: ='Equipo y maquinaria'!H$1/(B15*6*24.5) -> 0.52617669 | G15: =(C15*B15)+D15+E15+F15 -> 1008.1391 | H15: =G15/B15 -> 3.4058753
A16: 2 Pack Pepsi + Mirinda 3 lts | B16: 167 | C16: =(Tarifario!D$10/'Costos produccion'!B16) -> 4.5926522 | D16: =(VLOOKUP(A16,Tabla1[[Descripción]:[Costo etiqueta]],7,FALSE)*B16)+0.7*B16 -> 154.10426 | E16: =D16*0.05 -> 7.705213 | F16: ='Equipo y maquinaria'!H$1/(B16*6*24.5) -> 0.93262455 | G16: =(C16*B16)+D16+E16+F16 -> 929.71501 | H16: =G16/B16 -> 5.5671558
... A42: 12 Pack Jugazzo Lata Surtido | B42: 297 | C42: =(Tarifario!D$10/'Costos produccion'!B42) -> 2.5824004 | D42: =(VLOOKUP(A42,Tabla1[[Descripción]:[Costo etiqueta]],7,FALSE)*B42)+0.7*B42 -> 229.95522 | E42: =D42*0.05 -> 11.497761 | F42: ='Equipo y maquinaria'!H$1/(B42*6*24.5) -> 0.52440505 | G42: =(C42*B42)+D42+E42+F42 -> 1008.9503 | H42: =G42/B42 -> 3.3971391
